Workbook

Sheet Prospection
A1: N° | B1: Restaurant | C1: Type de cuisine | D1: Adresse | E1: Ville | F1: Téléphone | G1: Statut | H1: Date 1er contact | I1: Interlocuteur | J1: Prochaine action | K1: Date de relance | L1: Commentaires | M1: Carte
A2: 1 | B2: 450° par Pizzeria d'Alexis | C2: Pizza, Italienne | E2: Toulouse | G2: À contacter | M2: Voir la carte
A3: 2 | B3: @Pizza Plana | C3: Pizza | D3: 108 Rue Louis Plana | E3: Toulouse | G3: À contacter | M3: Voir la carte
A4: 3 | B4: A Mesa de Carole | C4: Portugaise | D4: 44 Avenue Antoine de Saint-Exupéry | E4: Toulouse | F4: 07 55 45 03 34 | G4: À contacter | M4: Voir la carte
A5: 4 | B5: A Taula | C5: Tapas | D5: 11 Rue Malcousinat | E5: Toulouse | F5: 07 69 47 85 86 | G5: À contacter | M5: Voir la carte
A6: 5 | B6: A.mar | C6: Fruits de mer | E6: Toulouse | G6: À contacter | M6: Voir la carte
A7: 6 | B7: Abuelo | C7: Méditerranéenne | E7: Toulouse | F7: 05 61 41 68 18 | G7: À contacter | M7: Voir la carte
A8: 7 | B8: Abyssinia | C8: Éthiopienne | E8: Toulouse | F8: 07 68 84 85 21 | G8: À contacter | M8: Voir la carte
A9: 8 | B9: Acte 2 | C9: Française, Gastronomique | E9: Toulouse | G9: À contacter | M9: Voir la carte
A10: 9 | B10: Adana grill | C10: Turque | D10: 16 Avenue de Larrieu-Thibaud | E10: Toulouse | F10: 05 31 47 30 59 | G10: À contacter | M10: Voir la carte
A11: 10 | B11: African Queen | C11: Africaine | E11: Toulouse | G11: À contacter | M11: Voir la carte
A12: 11 | B12: Agapes | C12: Gastronomique | E12: Toulouse | F12: 05 61 99 30 31 | G12: À contacter | M12: Voir la carte
A13: 12 | B13: Agora | E13: Toulouse | F13: 07 56 83 59 00 | G13: À contacter | M13: Voir la carte
A14: 13 | B14: Aiko | C14: Japonaise | E14: Toulouse | F14: 09 83 50 22 75 | G14: À contacter | M14: Voir la carte
A15: 14 | B15: Aishi Ramen | C15: Japonaise, Ramen | D15: 16 Rue Léon Gambetta | E15: Toulouse | G15: À contacter | M15: Voir la carte
A16: 15 | B16: Alice Pizza | C16: Pizza | E16: Toulouse | F16: 05 34 57 84 65 | G16: À contacter | M16: Voir la carte
A17: 16 | B17: Amore Mia | C17: Italienne, Française | E17: Toulouse | F17: 09 60 06 35 12 | G17: À contacter | M17: Voir la carte
A18: 17 | B18: An Nam | C18: Vietnamienne | E18: Toulouse | G18: À contacter | M18: Voir la carte
A19: 18 | B19: Andiamo | C19: Italienne | D19: 2 Avenue Paul Séjourné | E19: Toulouse | F19: 06 61 04 83 99 | G19: À contacter | M19: Voir la carte
A20: 19 | B20: Andochine | C20: Vietnamienne | D20: 28 Rue des Polinaires | E20: Toulouse | F20: 05 36 89 89 34 | G20: À contacter | M20: Voir la carte
A21: 20 | B21: Antho et Rita | D21: 63 Allées Charles de Fitte | E21: Toulouse | F21: 06 74 32 68 00 | G21: À contacter | M21: Voir la carte
A22: 21 | B22: Antica Salumeria | C22: Italienne | E22: Toulouse | G22: À contacter | M22: Voir la carte
A23: 22 | B23: Aozai | C23: Thaïlandaise | E23: Toulouse | G23: À contacter | M23: Voir la carte
A24: 23 | B24: Armenian Bakery | C24: Arménienne | D24: 74 Allées Jean Jaurès | E24: Toulouse | G24: À contacter | M24: Voir la carte
A25: 24 | B25: Artigiano | E25: Toulouse | G25: À contacter | M25: Voir la carte
A26: 25 | B26: Asia Village | C26: Asiatique | E26: Toulouse | F26: 05 61 57 94 45 | G26: À contacter | M26: Voir la carte
A27: 26 | B27: Assoiffés | C27: Française | E27: Toulouse | G27: À contacter | M27: Voir la carte
A28: 27 | B28: Au Bon Graillou | E28: Toulouse | F28: 05 61 21 80 19 | G28: À contacter | M28: Voir la carte
A29: 28 | B29: Au Buron | C29: Régionale / terroir | E29: Toulouse | F29: 05 61 22 14 65 | G29: À contacter | M29: Voir la carte
A30: 29 | B30: Au Comptoir | C30: Asiatique | E30: Toulouse | G30: À contacter | M30: Voir la carte
A31: 30 | B31: Au cœur de Tunis | C31: Pizza | E31: Toulouse | G31: À contacter | M31: Voir la carte
A32: 31 | B32: Au cœur de Tunis | D32: 32 Allées Charles de Fitte | E32: Toulouse | G32: À contacter | M32: Voir la carte
A33: 32 | B33: Au Gascon | C33: Française, Régionale / terroir | E33: Toulouse | F33: 05 61 21 67 16 | G33: À contacter | M33: Voir la carte
A34: 33 | B34: Au Gourmet Vietnam | C34: Vietnamienne, Asiatique | E34: Toulouse | F34: 05 32 98 64 76 | G34: À contacter | M34: Voir la carte
A35: 34 | B35: Au Jardin des Thés | E35: Toulouse | G35: À contacter | M35: Voir la carte
A36: 35 | B36: Au Pois Gourmand | D36: 3 Rue Émile Heybrard | E36: Toulouse | F36: 05 34 36 42 00 | G36: À contacter | M36: Voir la carte
A37: 36 | B37: Au Vieux Pékin | C37: Chinoise | E37: Toulouse | F37: 09 83 52 51 50 | G37: À contacter | M37: Voir la carte
A38: 37 | B38: Autour de Pizz' | C38: Pizza | D38: 1 Rue de Carcassonne | E38: Toulouse | F38: 05 61 80 28 62 | G38: À contacter | M38: Voir la carte
A39: 38 | B39: Aux 3 Elephants | C39: Chinoise | E39: Toulouse | G39: À contacter | M39: Voir la carte
A40: 39 | B40: Aux Délices D'Ailleurs | C40: Asiatique | D40: 2 Rue Paul Rocache | E40: Toulouse | F40: 05 61 44 16 56 | G40: À contacter | M40: Voir la carte
...

Sheet Synthèse
A1: Synthèse de la prospection - Restaurants de Toulouse
A2: Les compteurs se mettent à jour automatiquement à partir de la feuille Prospection (colonnes Statut et données).
A4: Statut | B4: Nombre | C4: Part
A5: À contacter | B5: =COUNTIF(Prospection!$G$2:$G$885,A5) -> 884 | C5: =IF($B$12=0,0,B5/$B$12) -> 1
A6: Contacté | B6: =COUNTIF(Prospection!$G$2:$G$885,A6) -> 0 | C6: =IF($B$12=0,0,B6/$B$12) -> 0
A7: RDV pris | B7: =COUNTIF(Prospection!$G$2:$G$885,A7) -> 0 | C7: =IF($B$12=0,0,B7/$B$12) -> 0
A8: Devis envoyé | B8: =COUNTIF(Prospection!$G$2:$G$885,A8) -> 0 | C8: =IF($B$12=0,0,B8/$B$12) -> 0
A9: Client | B9: =COUNTIF(Prospection!$G$2:$G$885,A9) -> 0 | C9: =IF($B$12=0,0,B9/$B$12) -> 0
A10: Pas intéressé | B10: =COUNTIF(Prospection!$G$2:$G$885,A10) -> 0 | C10: =IF($B$12=0,0,B10/$B$12) -> 0
A11: À relancer | B11: =COUNTIF(Prospection!$G$2:$G$885,A11) -> 0 | C11: =IF($B$12=0,0,B11/$B$12) -> 0
A12: Total des fiches | B12: =SUM(B5:B11) -> 884 | C12: =IF($B$12=0,0,B12/$B$12) -> 1
A14: Fiches traitées (statut différent de « À contacter ») | B14: =B12-B5 -> 0
A15: Taux de transformation (clients / fiches traitées) | B15: =IF(B14=0,0,B9/B14) -> 0
A16: Fiches à relancer ou en attente (RDV, devis, relance) | B16: =B7+B8+B11 -> 0
A18: Données disponibles | B18: Nombre | C18: Part
A19: Fiches avec téléphone | B19: =COUNTA(Prospection!$F$2:$F$885) -> 538 | C19: =IF($B$12=0,0,B19/$B$12) -> 0.60859729
A20: Fiches avec adresse | B20: =COUNTA(Prospection!$D$2:$D$885) -> 245 | C20: =IF($B$12=0,0,B20/$B$12) -> 0.27714932
A21: Fiches avec type de cuisine | B21: =COUNTA(Prospection!$C$2:$C$885) -> 611 | C21: =IF($B$12=0,0,B21/$B$12) -> 0.69117647
A23: Type de cuisine (20 plus fréquents) | B23: Fiches | C23: Part
A24: Française | B24: =COUNTIF(Prospection!$C$2:$C$885,"*"&A24&"*") -> 130 | C24: =IF($B$12=0,0,B24/$B$12) -> 0.14705882
A25: Pizza | B25: =COUNTIF(Prospection!$C$2:$C$885,"*"&A25&"*") -> 83 | C25: =IF($B$12=0,0,B25/$B$12) -> 0.093891403
A26: Asiatique | B26: =COUNTIF(Prospection!$C$2:$C$885,"*"&A26&"*") -> 51 | C26: =IF($B$12=0,0,B26/$B$12) -> 0.057692308
A27: Japonaise | B27: =COUNTIF(Prospection!$C$2:$C$885,"*"&A27&"*") -> 49 | C27: =IF($B$12=0,0,B27/$B$12) -> 0.055429864
A28: Italienne | B28: =COUNTIF(Prospection!$C$2:$C$885,"*"&A28&"*") -> 45 | C28: =IF($B$12=0,0,B28/$B$12) -> 0.050904977
A29: Régionale / terroir | B29: =COUNTIF(Prospection!$C$2:$C$885,"*"&A29&"*") -> 38 | C29: =IF($B$12=0,0,B29/$B$12) -> 0.042986425
A30: Chinoise | B30: =COUNTIF(Prospection!$C$2:$C$885,"*"&A30&"*") -> 26 | C30: =IF($B$12=0,0,B30/$B$12) -> 0.029411765
A31: Indienne | B31: =COUNTIF(Prospection!$C$2:$C$885,"*"&A31&"*") -> 24 | C31: =IF($B$12=0,0,B31/$B$12) -> 0.027149321
A32: Vietnamienne | B32: =COUNTIF(Prospection!$C$2:$C$885,"*"&A32&"*") -> 23 | C32: =IF($B$12=0,0,B32/$B$12) -> 0.0260181
A33: Tapas | B33: =COUNTIF(Prospection!$C$2:$C$885,"*"&A33&"*") -> 19 | C33: =IF($B$12=0,0,B33/$B$12) -> 0.021493213
A34: Sushi | B34: =COUNTIF(Prospection!$C$2:$C$885,"*"&A34&"*") -> 19 | C34: =IF($B$12=0,0,B34/$B$12) -> 0.021493213
A35: Burger | B35: =COUNTIF(Prospection!$C$2:$C$885,"*"&A35&"*") -> 19 | C35: =IF($B$12=0,0,B35/$B$12) -> 0.021493213
... A43: Salades | B43: =COUNTIF(Prospection!$C$2:$C$885,"*"&A43&"*") -> 10 | C43: =IF($B$12=0,0,B43/$B$12) -> 0.011312217
A45: Une fiche avec plusieurs types de cuisine est comptée dans chacun d'eux.

Sheet Aide
A1: Mode d'emploi du fichier de prospection
A3: Objet | B3: Suivi de la prospection commerciale des restaurants de Toulouse : une ligne par établissement, avec les colonnes de suivi à compléter au fil des contacts.
A4: Source des données | B4: Liste extraite d'OpenStreetMap (API Overpass) le 29/09/2026 avec le script lister_restaurants.py (dépôt GitHub Caillah31, dossier restaurants-france). 886 établissements listés, 2 doublons retirés (même nom et même téléphone ou adresse), 884 fiches conservées.
A5: Fiabilité | B5: Les données OpenStreetMap sont contributives : certains établissements n'ont pas de téléphone ou d'adresse, d'autres ont pu fermer. Vérifiez la fiche (lien « Voir la carte ») avant tout démarchage.
A6: Colonnes A à F | B6: Données de l'établissement (numéro, nom, type de cuisine, adresse, ville, téléphone). Vous pouvez les corriger si besoin. Le type de cuisine est traduit depuis les catégories OpenStreetMap.
A7: Colonnes G à L (fond jaune) | B7: Colonnes de suivi à remplir : Statut (liste déroulante), Date 1er contact, Interlocuteur, Prochaine action, Date de relance, Commentaires. Les dates se saisissent au format JJ/MM/AAAA.
A8: Colonne M | B8: Lien automatique vers une recherche Google Maps sur le nom et l'adresse de l'établissement.
A9: Statuts | B9: À contacter · Contacté · RDV pris · Devis envoyé · Client · Pas intéressé · À relancer. Le statut colore la cellule automatiquement ; la feuille Synthèse compte les fiches par statut.
A10: Filtres | B10: Les en-têtes de la feuille Prospection ont des filtres : filtrez par statut, par type de cuisine ou triez par date de relance pour préparer vos appels.
A11: Mettre à jour la liste | B11: Pour régénérer la liste (ou ajouter la périphérie toulousaine) : python3 lister_restaurants.py --peripherie --format csv --sortie toulouse.csv
A13: Exemple de ligne remplie
A14: Restaurant | B14: Chez Exemple (fictif)
A15: Type de cuisine | B15: Française
A16: Adresse | B16: 1 Rue de l'Exemple
A17: Ville | B17: Toulouse
A18: Téléphone | B18: 05 61 00 00 00
A19: Statut | B19: RDV pris
A20: Date 1er contact | B20: 02/10/2026
A21: Interlocuteur | B21: Mme Martin, gérante
A22: Prochaine action | B22: Présenter l'offre en rendez-vous
A23: Date de relance | B23: 09/10/2026
A24: Commentaires | B24: Intéressée par une démonstration, préfère être appelée le matin
A26: Ligne d'exemple fictive : elle n'est pas dans la feuille Prospection.
