Workbook

Sheet Prospection
A1: N° | B1: Restaurant | C1: Type de cuisine | D1: Adresse | E1: Code postal | F1: Commune | G1: Téléphone | H1: Site web | I1: Horaires | J1: Statut | K1: Date 1er contact | L1: Interlocuteur | M1: Prochaine action | N1: Date de relance | O1: Commentaires | P1: Carte | Q1: Fiche OSM
A2: 1 | B2: 450° par Pizzeria d'Alexis | C2: Pizza, Italienne | F2: Toulouse | J2: À contacter | P2: Voir la carte | Q2: Ouvrir
A3: 2 | B3: @Pizza Plana | C3: Pizza | D3: 108 Rue Louis Plana | E3: 31500 | F3: Toulouse | I3: Tu-Sa 11:30-14:00,18:30-21:45; Su 18:30-21:30 | J3: À contacter | P3: Voir la carte | Q3: Ouvrir
A4: 3 | B4: A Mesa de Carole | C4: Portugaise | D4: 44 Avenue Antoine de Saint-Exupéry | E4: 31400 | F4: Toulouse | G4: 07 55 45 03 34 | J4: À contacter | P4: Voir la carte | Q4: Ouvrir
A5: 4 | B5: A Taula | C5: Tapas | D5: 11 Rue Malcousinat | F5: Toulouse | G5: 07 69 47 85 86 | J5: À contacter | P5: Voir la carte | Q5: Ouvrir
A6: 5 | B6: A.mar | C6: Fruits de mer | F6: Toulouse | I6: Tu-Sa 12:00-14:00, 18:00-22:00 | J6: À contacter | P6: Voir la carte | Q6: Ouvrir
A7: 6 | B7: Abuelo | C7: Méditerranéenne | F7: Toulouse | G7: 05 61 41 68 18 | H7: https://www.abuelorestaurant.fr/ | I7: Tu-Sa 12:00-01:00 | J7: À contacter | P7: Voir la carte | Q7: Ouvrir
A8: 7 | B8: Abyssinia | C8: Éthiopienne | F8: Toulouse | G8: 07 68 84 85 21 | H8: https://restaurant-ethiopien-toulouse.eatbu.com/?lang=fr | I8: Tu-Su 12:00-14:30,18:30-23:00 | J8: À contacter | P8: Voir la carte | Q8: Ouvrir
A9: 8 | B9: Acte 2 | C9: Française, Gastronomique | F9: Toulouse | H9: https://yannickdelpech-acte2.fr/ | I9: Fr-Sa 12:00-14:00,Tu-Sa 20:00-22:00 | J9: À contacter | P9: Voir la carte | Q9: Ouvrir
A10: 9 | B10: Adana grill | C10: Turque | D10: 16 Avenue de Larrieu-Thibaud | E10: 31100 | F10: Toulouse | G10: 05 31 47 30 59 | H10: https://adana-grill-toulouse.fr | I10: Mo-Fr 11:30-23:00 | J10: À contacter | P10: Voir la carte | Q10: Ouvrir
A11: 10 | B11: African Queen | C11: Africaine | F11: Toulouse | J11: À contacter | P11: Voir la carte | Q11: Ouvrir
A12: 11 | B12: Agapes | C12: Gastronomique | F12: Toulouse | G12: 05 61 99 30 31 | H12: https://www.agapes-toulouse.fr/ | I12: Th-Sa 12:00-13:30; Tu-Sa 19:45-21:30 | J12: À contacter | P12: Voir la carte | Q12: Ouvrir
A13: 12 | B13: Agora | F13: Toulouse | G13: 07 56 83 59 00 | J13: À contacter | P13: Voir la carte | Q13: Ouvrir
A14: 13 | B14: Aiko | C14: Japonaise | F14: Toulouse | G14: 09 83 50 22 75 | H14: https://www.aikobistrot.com/ | I14: Tu-Th 12:00-14:00,19:30-22:00; Fr-Sa 12:00-14:30,19:30-22:30; Su,Mo off | J14: À contacter | P14: Voir la carte | Q14: Ouvrir
A15: 14 | B15: Aishi Ramen | C15: Japonaise, Ramen | D15: 16 Rue Léon Gambetta | F15: Toulouse | I15: Tu-Su 11:30-14:30,18:30-22:00 | J15: À contacter | P15: Voir la carte | Q15: Ouvrir
A16: 15 | B16: Alice Pizza | C16: Pizza | F16: Toulouse | G16: 05 34 57 84 65 | H16: https://www.alice-pizza.net/ | I16: PH; Mo-Sa 11:00-14:00,18:00-22:00; Su 18:00-22:00 | J16: À contacter | P16: Voir la carte | Q16: Ouvrir
A17: 16 | B17: Amore Mia | C17: Italienne, Française | F17: Toulouse | G17: 09 60 06 35 12 | H17: https://amore-mia.fr/ | I17: Tu 12:00-14:00; We-Sa 12:00-14:00,19:00-22:00; Su 11:00-14:30 | J17: À contacter | P17: Voir la carte | Q17: Ouvrir
A18: 17 | B18: An Nam | C18: Vietnamienne | F18: Toulouse | J18: À contacter | P18: Voir la carte | Q18: Ouvrir
A19: 18 | B19: Andiamo | C19: Italienne | D19: 2 Avenue Paul Séjourné | E19: 31000 | F19: Toulouse | G19: 06 61 04 83 99 | H19: https://andiamo-toulouse.eatbu.com | I19: Tu-Fr 12:00-14:00, Tu-Sa 19:00-22:00 | J19: À contacter | P19: Voir la carte | Q19: Ouvrir
A20: 19 | B20: Andochine | C20: Vietnamienne | D20: 28 Rue des Polinaires | E20: 31000 | F20: Toulouse | G20: 05 36 89 89 34 | H20: https://an-dochine.fr/ | I20: Mo-Sa 12:00-14:30,18:00-22:30; Su 12:00-14:30 | J20: À contacter | P20: Voir la carte | Q20: Ouvrir
A21: 20 | B21: Antho et Rita | D21: 63 Allées Charles de Fitte | F21: Toulouse | G21: 06 74 32 68 00 | I21: Mo, Tu 11:00-17:00; We-Fr 11:00-21:30 | J21: À contacter | P21: Voir la carte | Q21: Ouvrir
A22: 21 | B22: Antica Salumeria | C22: Italienne | F22: Toulouse | I22: "10h à l'aperitivo" | J22: À contacter | P22: Voir la carte | Q22: Ouvrir
A23: 22 | B23: Aozai | C23: Thaïlandaise | F23: Toulouse | J23: À contacter | P23: Voir la carte | Q23: Ouvrir
A24: 23 | B24: Armenian Bakery | C24: Arménienne | D24: 74 Allées Jean Jaurès | F24: Toulouse | I24: Mo-Fr 10:00-21:00; Sa 10:30-21:00; Su 12:00-21:00 | J24: À contacter | P24: Voir la carte | Q24: Ouvrir
A25: 24 | B25: Artigiano | F25: Toulouse | J25: À contacter | P25: Voir la carte | Q25: Ouvrir
A26: 25 | B26: Asia Village | C26: Asiatique | F26: Toulouse | G26: 05 61 57 94 45 | I26: Tu-Su 12:00-22:00 | J26: À contacter | P26: Voir la carte | Q26: Ouvrir
A27: 26 | B27: Assoiffés | C27: Française | F27: Toulouse | I27: Tu-Sa 10:00-24:00 | J27: À contacter | P27: Voir la carte | Q27: Ouvrir
A28: 27 | B28: Au Bon Graillou | F28: Toulouse | G28: 05 61 21 80 19 | H28: https://fr-fr.facebook.com/Au-Bon-Graillou-157630230940966/ | J28: À contacter | P28: Voir la carte | Q28: Ouvrir
A29: 28 | B29: Au Buron | C29: Régionale / terroir | F29: Toulouse | G29: 05 61 22 14 65 | H29: https://www.auburon.fr | I29: Mo-Fr 12:00-14:00,19:30-21:30; Sa 19:30-21:30 | J29: À contacter | P29: Voir la carte | Q29: Ouvrir
A30: 29 | B30: Au Comptoir | C30: Asiatique | F30: Toulouse | J30: À contacter | P30: Voir la carte | Q30: Ouvrir
A31: 30 | B31: Au cœur de Tunis | C31: Pizza | F31: Toulouse | J31: À contacter | P31: Voir la carte | Q31: Ouvrir
A32: 31 | B32: Au cœur de Tunis | D32: 32 Allées Charles de Fitte | F32: Toulouse | I32: Mo-Th 12:00-15:00, Fr 12:00-14:00, Sa,Su 12:00-22:00, Mo-Th 18:30-22:00, Fr 18:30-22:30 | J32: À contacter | P32: Voir la carte | Q32: Ouvrir
A33: 32 | B33: Au Gascon | C33: Française, Régionale / terroir | F33: Toulouse | G33: 05 61 21 67 16 | H33: https://www.restaurant-augascon-toulouse.fr/ | I33: Mo-Sa 11:30-14:00,19:00-22:00 | J33: À contacter | P33: Voir la carte | Q33: Ouvrir
A34: 33 | B34: Au Gourmet Vietnam | C34: Vietnamienne, Asiatique | F34: Toulouse | G34: 05 32 98 64 76 | H34: https://au-gourmet-vietnam.eatbu.com | I34: 11:30-14:00 open; Tu-Sa 18:30-21:00 "takeaway only" | J34: À contacter | P34: Voir la carte | Q34: Ouvrir
A35: 34 | B35: Au Jardin des Thés | F35: Toulouse | I35: Mo-Fr 11:30-15:30; Sa 11:30-16:00; Su 11:00-16:00 | J35: À contacter | P35: Voir la carte | Q35: Ouvrir
A36: 35 | B36: Au Pois Gourmand | D36: 3 Rue Émile Heybrard | E36: 31300 | F36: Toulouse | G36: 05 34 36 42 00 | H36: https://pois-gourmand.fr/ | I36: Mo-Sa 19:30-21:30, Mo-Fr 12:00-13:30 | J36: À contacter | P36: Voir la carte | Q36: Ouvrir
A37: 36 | B37: Au Vieux Pékin | C37: Chinoise | F37: Toulouse | G37: 09 83 52 51 50 | H37: http://www.auvieuxpekin.fr | J37: À contacter | P37: Voir la carte | Q37: Ouvrir
A38: 37 | B38: Autour de Pizz' | C38: Pizza | D38: 1 Rue de Carcassonne | E38: 31500 | F38: Toulouse | G38: 05 61 80 28 62 | H38: https://autour-de-pizz.metro.rest | J38: À contacter | P38: Voir la carte | Q38: Ouvrir
A39: 38 | B39: Aux 3 Elephants | C39: Chinoise | F39: Toulouse | J39: À contacter | P39: Voir la carte | Q39: Ouvrir
A40: 39 | B40: Aux Délices D'Ailleurs | C40: Asiatique | D40: 2 Rue Paul Rocache | E40: 31100 | F40: Toulouse | G40: 05 61 44 16 56 | J40: À contacter | P40: Voir la carte | Q40: Ouvrir
...

Sheet Synthèse
A1: Synthèse de la prospection - Toulouse et périphérie (5 km)
A2: Les compteurs se mettent à jour automatiquement à partir de la feuille Prospection.
A4: Statut | B4: Nombre | C4: Part
A5: À contacter | B5: =COUNTIF(Prospection!$J$2:$J$1431,A5) -> 1430 | C5: =IF($B$12=0,0,B5/$B$12) -> 1
A6: Contacté | B6: =COUNTIF(Prospection!$J$2:$J$1431,A6) -> 0 | C6: =IF($B$12=0,0,B6/$B$12) -> 0
A7: RDV pris | B7: =COUNTIF(Prospection!$J$2:$J$1431,A7) -> 0 | C7: =IF($B$12=0,0,B7/$B$12) -> 0
A8: Devis envoyé | B8: =COUNTIF(Prospection!$J$2:$J$1431,A8) -> 0 | C8: =IF($B$12=0,0,B8/$B$12) -> 0
A9: Client | B9: =COUNTIF(Prospection!$J$2:$J$1431,A9) -> 0 | C9: =IF($B$12=0,0,B9/$B$12) -> 0
A10: Pas intéressé | B10: =COUNTIF(Prospection!$J$2:$J$1431,A10) -> 0 | C10: =IF($B$12=0,0,B10/$B$12) -> 0
A11: À relancer | B11: =COUNTIF(Prospection!$J$2:$J$1431,A11) -> 0 | C11: =IF($B$12=0,0,B11/$B$12) -> 0
A12: Total des fiches | B12: =SUM(B5:B11) -> 1430 | C12: =IF($B$12=0,0,B12/$B$12) -> 1
A14: Fiches traitées (statut différent de « À contacter ») | B14: =B12-B5 -> 0
A15: Taux de transformation (clients / fiches traitées) | B15: =IF(B14=0,0,B9/B14) -> 0
A16: Fiches en attente (RDV, devis, relance) | B16: =B7+B8+B11 -> 0
A18: Données disponibles | B18: Nombre | C18: Part
A19: Fiches avec téléphone | B19: =COUNTA(Prospection!$G$2:$G$1431) -> 782 | C19: =IF($B$12=0,0,B19/$B$12) -> 0.54685315
A20: Fiches avec adresse | B20: =COUNTA(Prospection!$D$2:$D$1431) -> 454 | C20: =IF($B$12=0,0,B20/$B$12) -> 0.31748252
A21: Fiches avec site web | B21: =COUNTA(Prospection!$H$2:$H$1431) -> 718 | C21: =IF($B$12=0,0,B21/$B$12) -> 0.5020979
A22: Fiches avec horaires | B22: =COUNTA(Prospection!$I$2:$I$1431) -> 842 | C22: =IF($B$12=0,0,B22/$B$12) -> 0.58881119
A23: Fiches avec type de cuisine | B23: =COUNTA(Prospection!$C$2:$C$1431) -> 955 | C23: =IF($B$12=0,0,B23/$B$12) -> 0.66783217
A26: Commune | B26: Fiches | C26: Part | D26: Traitées | E26: Clients
A27: Toulouse | B27: =COUNTIF(Prospection!$F$2:$F$1431,A27) -> 884 | C27: =IF($B$12=0,0,B27/$B$12) -> 0.61818182 | D27: =B27-COUNTIFS(Prospection!$F$2:$F$1431,A27,Prospection!$J$2:$J$1431,"À contacter") -> 0 | E27: =COUNTIFS(Prospection!$F$2:$F$1431,A27,Prospection!$J$2:$J$1431,"Client") -> 0
A28: Colomiers | B28: =COUNTIF(Prospection!$F$2:$F$1431,A28) -> 39 | C28: =IF($B$12=0,0,B28/$B$12) -> 0.027272727 | D28: =B28-COUNTIFS(Prospection!$F$2:$F$1431,A28,Prospection!$J$2:$J$1431,"À contacter") -> 0 | E28: =COUNTIFS(Prospection!$F$2:$F$1431,A28,Prospection!$J$2:$J$1431,"Client") -> 0
A29: Tournefeuille | B29: =COUNTIF(Prospection!$F$2:$F$1431,A29) -> 26 | C29: =IF($B$12=0,0,B29/$B$12) -> 0.018181818 | D29: =B29-COUNTIFS(Prospection!$F$2:$F$1431,A29,Prospection!$J$2:$J$1431,"À contacter") -> 0 | E29: =COUNTIFS(Prospection!$F$2:$F$1431,A29,Prospection!$J$2:$J$1431,"Client") -> 0
A30: Blagnac | B30: =COUNTIF(Prospection!$F$2:$F$1431,A30) -> 68 | C30: =IF($B$12=0,0,B30/$B$12) -> 0.047552448 | D30: =B30-COUNTIFS(Prospection!$F$2:$F$1431,A30,Prospection!$J$2:$J$1431,"À contacter") -> 0 | E30: =COUNTIFS(Prospection!$F$2:$F$1431,A30,Prospection!$J$2:$J$1431,"Client") -> 0
A31: Muret | B31: =COUNTIF(Prospection!$F$2:$F$1431,A31) -> 34 | C31: =IF($B$12=0,0,B31/$B$12) -> 0.023776224 | D31: =B31-COUNTIFS(Prospection!$F$2:$F$1431,A31,Prospection!$J$2:$J$1431,"À contacter") -> 0 | E31: =COUNTIFS(Prospection!$F$2:$F$1431,A31,Prospection!$J$2:$J$1431,"Client") -> 0
A32: Cugnaux | B32: =COUNTIF(Prospection!$F$2:$F$1431,A32) -> 30 | C32: =IF($B$12=0,0,B32/$B$12) -> 0.020979021 | D32: =B32-COUNTIFS(Prospection!$F$2:$F$1431,A32,Prospection!$J$2:$J$1431,"À contacter") -> 0 | E32: =COUNTIFS(Prospection!$F$2:$F$1431,A32,Prospection!$J$2:$J$1431,"Client") -> 0
A33: Plaisance-du-Touch | B33: =COUNTIF(Prospection!$F$2:$F$1431,A33) -> 20 | C33: =IF($B$12=0,0,B33/$B$12) -> 0.013986014 | D33: =B33-COUNTIFS(Prospection!$F$2:$F$1431,A33,Prospection!$J$2:$J$1431,"À contacter") -> 0 | E33: =COUNTIFS(Prospection!$F$2:$F$1431,A33,Prospection!$J$2:$J$1431,"Client") -> 0
A34: Balma | B34: =COUNTIF(Prospection!$F$2:$F$1431,A34) -> 22 | C34: =IF($B$12=0,0,B34/$B$12) -> 0.015384615 | D34: =B34-COUNTIFS(Prospection!$F$2:$F$1431,A34,Prospection!$J$2:$J$1431,"À contacter") -> 0 | E34: =COUNTIFS(Prospection!$F$2:$F$1431,A34,Prospection!$J$2:$J$1431,"Client") -> 0
A35: Ramonville-Saint-Agne | B35: =COUNTIF(Prospection!$F$2:$F$1431,A35) -> 19 | C35: =IF($B$12=0,0,B35/$B$12) -> 0.013286713 | D35: =B35-COUNTIFS(Prospection!$F$2:$F$1431,A35,Prospection!$J$2:$J$1431,"À contacter") -> 0 | E35: =COUNTIFS(Prospection!$F$2:$F$1431,A35,Prospection!$J$2:$J$1431,"Client") -> 0
A36: Castanet-Tolosan | B36: =COUNTIF(Prospection!$F$2:$F$1431,A36) -> 16 | C36: =IF($B$12=0,0,B36/$B$12) -> 0.011188811 | D36: =B36-COUNTIFS(Prospection!$F$2:$F$1431,A36,Prospection!$J$2:$J$1431,"À contacter") -> 0 | E36: =COUNTIFS(Prospection!$F$2:$F$1431,A36,Prospection!$J$2:$J$1431,"Client") -> 0
A37: Saint-Orens-de-Gameville | B37: =COUNTIF(Prospection!$F$2:$F$1431,A37) -> 12 | C37: =IF($B$12=0,0,B37/$B$12) -> 0.0083916084 | D37: =B37-COUNTIFS(Prospection!$F$2:$F$1431,A37,Prospection!$J$2:$J$1431,"À contacter") -> 0 | E37: =COUNTIFS(Prospection!$F$2:$F$1431,A37,Prospection!$J$2:$J$1431,"Client") -> 0
A38: Fonsorbes | B38: =COUNTIF(Prospection!$F$2:$F$1431,A38) -> 3 | C38: =IF($B$12=0,0,B38/$B$12) -> 0.0020979021 | D38: =B38-COUNTIFS(Prospection!$F$2:$F$1431,A38,Prospection!$J$2:$J$1431,"À contacter") -> 0 | E38: =COUNTIFS(Prospection!$F$2:$F$1431,A38,Prospection!$J$2:$J$1431,"Client") -> 0
... A85: Mondouzil | B85: =COUNTIF(Prospection!$F$2:$F$1431,A85) -> 1 | C85: =IF($B$12=0,0,B85/$B$12) -> 0.0006993007 | D85: =B85-COUNTIFS(Prospection!$F$2:$F$1431,A85,Prospection!$J$2:$J$1431,"À contacter") -> 0 | E85: =COUNTIFS(Prospection!$F$2:$F$1431,A85,Prospection!$J$2:$J$1431,"Client") -> 0
A86: Total | B86: =SUM(B27:B85) -> 1430 | D86: =SUM(D27:D85) -> 0 | E86: =SUM(E27:E85) -> 0
A89: Type de cuisine (20 plus fréquents) | B89: Fiches | C89: Part
A90: Française | B90: =COUNTIF(Prospection!$C$2:$C$1431,"*"&A90&"*") -> 199 | C90: =IF($B$12=0,0,B90/$B$12) -> 0.13916084
A91: Pizza | B91: =COUNTIF(Prospection!$C$2:$C$1431,"*"&A91&"*") -> 162 | C91: =IF($B$12=0,0,B91/$B$12) -> 0.11328671
A92: Asiatique | B92: =COUNTIF(Prospection!$C$2:$C$1431,"*"&A92&"*") -> 79 | C92: =IF($B$12=0,0,B92/$B$12) -> 0.055244755
A93: Italienne | B93: =COUNTIF(Prospection!$C$2:$C$1431,"*"&A93&"*") -> 78 | C93: =IF($B$12=0,0,B93/$B$12) -> 0.054545455
...

Sheet Aide
A1: Mode d'emploi du fichier de prospection
A3: Objet | B3: Suivi de la prospection commerciale des restaurants : Toulouse et périphérie (5 km). Une ligne par établissement, avec les colonnes de suivi à compléter au fil des contacts.
A4: Source des données | B4: Liste extraite d'OpenStreetMap (API Overpass) le 30/09/2026 avec le script lister_restaurants.py. 1435 établissements listés, 5 doublons retirés (même commune, même nom et même téléphone ou adresse), 1430 fiches conservées, 59 communes.
A5: Fiabilité | B5: Les données OpenStreetMap sont contributives : certains établissements n'ont pas de téléphone ou d'adresse, d'autres ont pu fermer. Vérifiez la fiche (liens « Voir la carte » et « Ouvrir ») avant tout démarchage.
A6: Colonnes A à I | B6: Données de l'établissement : numéro, nom, type de cuisine (traduit des catégories OpenStreetMap), adresse, code postal, commune, téléphone au format français, site web (cliquable), horaires (notation OpenStreetMap : Mo-Fr 12:00-14:00 = du lundi au vendredi de 12 h à 14 h). Vous pouvez les corriger si besoin.
A7: Colonnes J à O (fond jaune) | B7: Colonnes de suivi à remplir : Statut (liste déroulante), Date 1er contact, Interlocuteur, Prochaine action, Date de relance, Commentaires. Les dates se saisissent au format JJ/MM/AAAA.
A8: Colonnes P et Q | B8: Liens automatiques : position exacte sur Google Maps, et fiche OpenStreetMap de l'établissement.
A9: Statuts | B9: À contacter · Contacté · RDV pris · Devis envoyé · Client · Pas intéressé · À relancer. Le statut colore la cellule ; la feuille Synthèse compte les fiches par statut, par commune (avec fiches traitées et clients) et par type de cuisine.
A10: Filtres | B10: Les en-têtes de la feuille Prospection ont des filtres : filtrez par commune ou par type de cuisine, triez par date de relance pour préparer vos appels.
A11: Mettre à jour | B11: Régénérer le CSV : python3 lister_restaurants.py --peripherie --format csv --sortie export.csv, puis ce classeur : python3 prospection_xlsx.py export.csv prospection.xlsx
A13: Exemple de ligne remplie
A14: Restaurant | B14: Chez Exemple (fictif)
A15: Type de cuisine | B15: Française
A16: Adresse | B16: 1 Rue de l'Exemple
A17: Code postal | B17: 31000
A18: Commune | B18: Toulouse
A19: Téléphone | B19: 05 61 00 00 00
A20: Site web | B20: https://exemple.fr
A21: Horaires | B21: Mo-Sa 12:00-14:00,19:00-22:00
A22: Statut | B22: RDV pris
A23: Date 1er contact | B23: 02/10/2026
A24: Interlocuteur | B24: Mme Martin, gérante
A25: Prochaine action | B25: Présenter l'offre en rendez-vous
... A27: Commentaires | B27: Intéressée par une démonstration, préfère être appelée le matin
A29: Ligne d'exemple fictive : elle n'est pas dans la feuille Prospection.
