Workbook

Sheet Lisez-moi
B1: Fichier de prospection – aide-soignante diplômée au Cameroun – secteur des Arènes (Toulouse)
B2: Version du 30/09/2026. Informations issues de recherches web à cette date : vérifier téléphone et interlocuteur avant chaque contact.
B4: 1. À quoi sert ce fichier
B5: Objectif | C5: Trouver rapidement un premier emploi dans une structure de soins autour des Arènes, en tenant compte de deux contraintes : le diplôme camerounais d'aide-soignante n'est pas reconnu en France, et une autorisation de travail est nécessaire. Le fichier liste 73 employeurs potentiels dans un rayon de 6 km, avec le poste réaliste à viser pour chacun, et permet de suivre les contacts.
B6: Onglets | C6: Prospection : la liste des structures et le suivi des contacts (à remplir). Tableau de bord : compteurs automatiques (statuts, relances en retard, priorités). Parcours administratif : les 10 étapes (diplôme, autorisation de travail, métiers en tension, VAE, IFAS) avec organismes, pièces et sources. IFAS & formations : les écoles d'aides-soignants de Toulouse et leurs dates 2026-2027. Contacts utiles : administrations, France Travail, associations d'aide juridique. Modèles : emails de candidature, script téléphonique, argumentaire « autorisation de travail » pour l'employeur, réponses aux objections, check-list des pièces.
B8: 2. Légende et mode d'emploi
B9: Cellules jaunes | C9: Cellules à remplir par vous (suivi des contacts, cases « Fait », notes). Tout le reste est pré-rempli.
B10: Cellules blanches | C10: Données de recherche (adresse, téléphone, remarque, source). « à vérifier » = information non confirmée ; la source est en colonne R.
B11: Priorité (colonne P) | C11: 1 = à contacter en premier (proche, gros volume de recrutement, ouvert aux profils sans DEAS). 2 = à contacter ensuite. 3 = utile plus tard (nécessite le DEAS, ou éloigné, ou information à vérifier).
B12: Statut suivi (colonne S) | C12: Liste déroulante : À contacter → Contacté – en attente → Relance à faire → Entretien → Embauche / positif, Réponse négative ou Clos. Le Tableau de bord se met à jour automatiquement.
B13: Prochaine relance (colonne X) | C13: Saisir une date (jj/mm/aaaa). Les lignes dont la date de relance est dépassée passent en rouge clair ; le Tableau de bord les compte.
B14: Exemple de ligne remplie (colonnes S à Y) | C14: Statut : Contacté – en attente | Date 1er contact : 02/10/2026 | Canal : Téléphone | Interlocuteur : Mme Dupont, cadre de santé | Réponse : intéressée par un poste d'agent de soins de nuit, demande CV + attestation | Prochaine relance : 09/10/2026 | Notes : envoyer le CV le jour même, rappeler jeudi matin.
B15: Filtrer / trier | C15: La ligne d'en-tête de l'onglet Prospection possède des filtres : trier par Priorité, par Catégorie ou par Distance ; filtrer sur « Poste à viser » = « Aide à domicile / auxiliaire de vie » pour une session d'appels dédiée.
B17: 3. La stratégie en 7 points (détail dans « Parcours administratif »)
B18: 1. Ne pas postuler comme « aide-soignante » | C18: Sans DEAS français, ce titre ne peut pas être utilisé (aucune équivalence pour les diplômes hors UE, Croix-Rouge Cameroun incluse). Postuler comme ASH / agent de service hospitalier, agent de soins en EHPAD, ou aide à domicile / auxiliaire de vie : postes accessibles sans diplôme, très demandés autour des Arènes.
B19: 2. Mettre en avant l'expérience | C19: L'attestation de réussite camerounaise et surtout les attestations d'employeurs (soins d'hygiène et de confort, aide aux repas, mobilisation) sont les arguments : un employeur d'EHPAD préfère un agent de soins déjà formé aux gestes.
B20: 3. Les métiers visés sont « en tension » en Occitanie | C20: Aides à domicile, agents d'entretien de locaux (poste ASH) et aides-soignants figurent sur la liste de l'arrêté du 21 mai 2025 : l'employeur n'a pas à publier l'offre 3 semaines avant de demander l'autorisation de travail. Argument décisif, à expliquer avec l'onglet Modèles.
B21: 4. L'autorisation de travail est une formalité en ligne pour l'employeur | C21: Dépôt gratuit sur le portail ANEF, réponse sous 2 mois. Lui fournir la liste des pièces prête (onglet Modèles). Si son titre ou récépissé porte déjà la mention « autorise à travailler », aucune démarche n'est nécessaire : le vérifier en premier.
B22: 5. Demander la formation de 70 heures dès l'embauche | C22: Elle permet à un ASH de participer aux soins d'hygiène et de confort, et ouvre l'entrée directe en IFAS (sans sélection) après 6 mois de poste.
B23: 6. Lancer la VAE du DEAS en parallèle | C23: Sur vae.gouv.fr : l'expérience camerounaise compte sur justificatifs. Parcours de 6 à 12 mois, finançable CPF / France Travail. Rassembler dès maintenant les attestations d'employeurs du Cameroun.
B24: 7. S'inscrire à France Travail (agence Arènes) | C24: Indispensable pour la gratuité de la formation IFAS financée par la Région Occitanie, et pour le financement VAE. Session Croix-Rouge Toulouse encore ouverte jusqu'au 10 octobre 2026 pour une rentrée le 5 janvier 2027.
B26: 4. Informations à préciser pour affiner le fichier
B27: Situation administrative | C27: Quel titre de séjour ou récépissé possède-t-elle aujourd'hui (vie privée et familiale, étudiant, demandeur d'asile, récépissé, aucun) ? Cela change la démarche : dispense d'autorisation de travail, plafond de 964 h pour une étudiante, ou admission exceptionnelle au séjour « métiers en tension » (à déposer avant le 31/12/2026).
B28: Expérience | C28: Combien d'années d'exercice au Cameroun, dans quelles structures, et peut-elle obtenir des attestations d'employeur ? (Décisif pour la VAE.)
B29: Mobilité et horaires | C29: Permis / voiture ou transports en commun uniquement ? Acceptation des nuits, week-ends, coupures ? (Permet d'élargir ou de resserrer le rayon et de cibler les EHPAD de nuit.)
B30: Niveau de français écrit | C30: Suffisant pour le dossier VAE et l'entretien IFAS ? (Sinon, prévoir un accompagnement.)
B32: 5. Sources principales
C33: Arrêté du 21 mai 2025 fixant la liste des métiers en tension : https://www.legifrance.gouv.fr/jorf/id/JORFTEXT000051643488
C34: Autorisation de travail (service-public) : https://www.service-public.gouv.fr/particuliers/vosdroits/F2728
C35: Admission exceptionnelle au séjour métiers en tension : https://www.service-public.gouv.fr/particuliers/vosdroits/F16053
C36: Reconnaissance des diplômes paramédicaux (DREETS) : https://bourgogne-franche-comte.dreets.gouv.fr/Dispositif-de-reconnaissance-des-diplomes-paramedicaux
C37: France VAE – DEAS : https://vae.gouv.fr
C38: Annuaire officiel des EHPAD et services à domicile : https://www.pour-les-personnes-agees.gouv.fr
C39: Recrutement CHU de Toulouse : https://recrutement.chu-toulouse.fr ; CCAS de Toulouse : https://metropole.toulouse.fr/le-ccas-recrute

Sheet Prospection
A1: N° | B1: Nom | C1: Catégorie | D1: Type précis | E1: Groupe / gestionnaire | F1: Statut juridique | G1: Adresse | H1: CP | I1: Quartier / commune | J1: Distance (km) | K1: Téléphone | L1: Site / page recrutement | M1: Email / contact RH | N1: Capacité | O1: Poste à viser | P1: Priorité | Q1: Remarque | R1: Source | S1: Statut suivi | T1: Date 1er contact | U1: Canal | V1: Interlocuteur | W1: Réponse / résumé | X1: Prochaine relance | Y1: Notes
A2: 1 | B2: Clinique Pasteur | C2: Clinique / SMR | D2: Clinique MCO + HAD | E2: SA Clinique Pasteur (indépendante) | F2: Privé lucratif | G2: 45 avenue de Lombez, BP 27617 | H2: 31300 | I2: Arènes / Lombez | J2: 1 | K2: 05 62 21 31 31 ; RH 05 62 21 36 54 | L2: https://talents.clinique-pasteur.com/ | M2: à vérifier | N2: 469 à 516 lits et places | O2: ASH / agent de service | P2: 1 | Q2: La plus proche des Arènes. Candidature spontanée possible sur le portail talents. Postes ASH / agent hôtelier ; AS (après DEAS) y compris en HAD. | R2: https://www.clinique-pasteur.com/recrutement | S2: À contacter
A3: 2 | B3: Petits-fils Toulouse Ouest | C3: Domicile (SAAD / SSIAD / HAD) | D3: Aide à domicile (mandataire, auxiliaires de vie) | E3: Franchise Petits-fils | F3: Privé lucratif | G3: 197 rue des Fontaines | H3: 31300 | I3: Fontaine-Lestang | J3: 1 | K3: 05 32 11 17 50 | L3: https://www.petits-fils.com | M3: toulouse-ouest@petits-fils.com | N3: — | O3: Aide à domicile / auxiliaire de vie | P3: 1 | Q3: À 1 km. Recrute des auxiliaires de vie avec expérience (profil AS accepté). Autre agence à Tournefeuille. | R3: https://www.conseildependance.fr/services/services-a-domicile/toulouse/haute-garonne-31/petits-fils-toulouse-ouest | S3: À contacter
A4: 3 | B4: Colisée – Résidence Arc-en-Ciel | C4: EHPAD / résidence | D4: EHPAD (unité Alzheimer) | E4: Colisée | F4: Privé lucratif | G4: 12 rue Marie-Louise Dissard | H4: 31300 | I4: Cartoucherie | J4: 1.2 | K4: 05 61 16 40 00 | L4: https://colisee.fr (rubrique carrières) | M4: à vérifier | N4: 86 places | O4: Agent de soins / ASH (EHPAD) | P4: 1 | Q4: Grand groupe, recrutements agents de soins / ASH fréquents. Très proche. | R4: https://colisee.fr/residences/maison-medicalisee-toulouse-residence-arc-en-ciel/ | S4: À contacter
A5: 4 | B5: Résidence Edenis La Cartoucherie | C5: EHPAD / résidence | D5: EHPAD (14 places UVP Alzheimer) | E5: Edenis (association) | F5: Associatif / ESPIC | G5: 4 allée Bertha von Suttner | H5: 31300 | I5: Cartoucherie | J5: 1.3 | K5: 05 82 08 15 27 | L5: https://la-cartoucherie.edenis.fr ; https://edenis.fr (recrutement) | M5: à vérifier | N5: 88 lits | O5: Agent de soins / ASH (EHPAD) | P5: 1 | Q5: Groupe associatif toulousain (12+ EHPAD) : une candidature peut être diffusée à toutes les résidences. | R5: https://la-cartoucherie.edenis.fr/la-residence/ | S5: À contacter
A6: 5 | B6: EHPAD Gaubert (CCAS de Toulouse) | C6: EHPAD / résidence | D6: EHPAD (14 places Alzheimer) | E6: CCAS de Toulouse | F6: Public | G6: 28 rue Sainte-Lucie | H6: 31300 | I6: Saint-Cyprien | J6: 1.3 | K6: 05 34 56 54 00 | L6: https://metropole.toulouse.fr/le-ccas-recrute | M6: recrutement@ccas-toulouse.fr | N6: 60 lits | O6: Agent de soins / ASH (EHPAD) | P6: 1 | Q6: CCAS = 1 400 agents, 8 EHPAD, 6 résidences autonomie, SSIAD/SAAD. UNE seule adresse de candidature spontanée pour toutes ses structures. | R6: https://metropole.toulouse.fr/annuaire/ehpad-gaubert | S6: À contacter
A7: 6 | B7: Adecco Medical Toulouse | C7: Intérim / plateforme | D7: Intérim médical (agences Santé, Social & Handicap) | E7: Adecco Group | F7: Privé lucratif | G7: 43 avenue de Grande-Bretagne | H7: 31300 | I7: Purpan / Patte d'Oie | J7: 1.3 | K7: 05 62 73 74 00 | L7: https://www.adecco.com/fr-fr/medical | M7: toulouse@adeccomedical.fr | N7: — | O7: Missions ASH / agent de soins (intérim) | P7: 1 | Q7: Missions ASH / agent de soins en EHPAD et clinique. L'agence Social & Handicap couvre MAS/FAM. Attention : l'intérim exige aussi une autorisation de travail valide. | R7: https://www.adecco.com/fr-fr/medical/agences/occitanie/toulouse/adecco-medical-toulouse | S7: À contacter
A8: 7 | B8: Hôpital Joseph Ducuing | C8: Hôpital | D8: Hôpital MCO de proximité (urgences, SMR, USP) | E8: Association Hôpital Joseph Ducuing | F8: Associatif / ESPIC | G8: 15 rue de Varsovie | H8: 31300 | I8: Saint-Cyprien | J8: 1.5 | K8: 05 61 77 34 00 | L8: https://www.hopitaljosephducuing.fr/espace-recrutement | M8: à vérifier | N8: 171 lits et places | O8: ASH / agent de service | P8: 1 | Q8: Très proche. Espace recrutement en ligne ; offres AS régulières. Voisin de l'EHPAD Les Tilleuls (même association). | R8: https://www.hopitaljosephducuing.fr/espace-recrutement | S8: À contacter
A9: 8 | B9: EHPAD Résidence Les Tilleuls | C9: EHPAD / résidence | D9: EHPAD | E9: Association des Amis de la Médecine Sociale (liée à l'Hôpital Ducuing) | F9: Associatif / ESPIC | G9: 19 rue de Varsovie | H9: 31300 | I9: Saint-Cyprien | J9: 1.5 | K9: à vérifier | L9: à vérifier | M9: à vérifier | N9: à vérifier | O9: Agent de soins / ASH (EHPAD) | P9: 1 | Q9: Voisin immédiat de l'Hôpital Ducuing : se présenter sur place. | R9: https://www.pour-les-personnes-agees.gouv.fr/annuaire-ehpad-et-maisons-de-retraite/ehpad/haute-garonne-31/toulouse-31000/ehpad-residence-les-tilleuls/310792015 | S9: À contacter
A10: 9 | B10: DomusVi – Résidence La Cépière | C10: EHPAD / résidence | D10: EHPAD (12 places Alzheimer) | E10: DomusVi | F10: Privé lucratif | G10: 12 impasse de l'Hippodrome | H10: 31100 | I10: Cépière / Bagatelle | J10: 1.5 | K10: à vérifier | L10: https://www.domusvi.com (espace recrutement) | M10: à vérifier | N10: 80 lits | O10: Agent de soins / ASH (EHPAD) | P10: 1 | Q10: Grand groupe, offres agents de soins / ASH fréquentes. Très proche. | R10: https://www.leguidedupatrimoine.com/ehpad/domusvi-la-cepiere | S10: À contacter
A11: 10 | B11: Clinique Rive Gauche (ex Sarrus-Teinturiers) | C11: Clinique / SMR | D11: Clinique MCO + maternité | E11: SAS Clinique Rive Gauche (indépendante) | F11: Privé lucratif | G11: 49-51 allées Charles de Fitte | H11: 31300 | I11: Saint-Cyprien | J11: 1.7 | K11: 05 61 77 33 33 | L11: https://www.clinique-rivegauche.fr/espace-recrutement | M11: à vérifier | N11: 165-190 lits et places | O11: ASH / agent de service | P11: 1 | Q11: Très proche. Espace recrutement en ligne ; offres AS et ASH régulières. | R11: https://www.clinique-rivegauche.fr/espace-recrutement | S11: À contacter
A12: 11 | B12: EHPAD Les Fontaines (CCAS, ex Pierre Ducis) | C12: EHPAD / résidence | D12: EHPAD | E12: CCAS de Toulouse | F12: Public | G12: 92 avenue de Casselardit | H12: 31300 | I12: Casselardit | J12: 2 | K12: 05 34 50 80 00 | L12: https://metropole.toulouse.fr/le-ccas-recrute | M12: recrutement@ccas-toulouse.fr | N12: 85 places | O12: Agent de soins / ASH (EHPAD) | P12: 1 | Q12: Proche. Candidature via l'adresse CCAS + appel direct à la résidence. | R12: https://metropole.toulouse.fr/annuaire/ehpad-les-fontaines | S12: À contacter
A13: 12 | B13: CHU Toulouse – Hôpital Purpan | C13: Hôpital | D13: Hôpital (urgences, réanimation, médecine, chirurgie) | E13: CHU de Toulouse | F13: Public | G13: 1 place du Docteur Joseph Baylac | H13: 31300 | I13: Purpan | J13: 2.5 | K13: 05 61 77 22 33 | L13: https://recrutement.chu-toulouse.fr/candidature-spontanee/ | M13: à vérifier | N13: Site de 7 établissements | O13: ASH / agent de service | P13: 1 | Q13: Le CHU recrute des ASH en continu (contractuels, pas de condition de nationalité). Candidature spontanée en 4 étapes sur le portail. Voie IFAS « article 11 » après 6 mois + 70 h. | R13: https://recrutement.chu-toulouse.fr/candidature-spontanee/ | S13: À contacter
... A40: 39 | B40: EHPAD Louis Douste-Blazy (CCAS) | C40: EHPAD / résidence | D40: EHPAD à orientation psychiatrique | E40: CCAS de Toulouse | F40: Public | G40: 3 rue de Jérusalem | H40: 31100 | I40: Bellefontaine | J40: 3.5 | K40: à vérifier | L40: https://metropole.toulouse.fr/le-ccas-recrute | M40: recrutement@ccas-toulouse.fr | N40: 70 résidents | O40: Agent de soins / ASH (EHPAD) | P40: 2 | Q40: Ouvert en 2019. | R40: https://www.mazette.fr/ehpad/haute-garonne/louis-douste-blazy-toulouse | S40: À contacter
A41: 40 | B41: Senior Compagnie Toulouse Est-Ouest | C41: Domicile (SAAD / SSIAD / HAD) | D41: SAAD | E41: Franchise Senior Compagnie | F41: Privé lucratif | G41: 9 allée Frédéric Mistral | H41: 31400 | I41: Saint-Agne / Busca | J41: 3.5 | K41: 05 61 00 53 86 | L41: https://senior-compagnie.fr | M41: à vérifier | N41: — | O41: Aide à domicile / auxiliaire de vie | P41: 2 | R41: https://senior-compagnie.fr/agence/haute-garonne/aide-a-domicile-a-toulouse-est-ouest/ | S41: À contacter
A42: 41 | B42: Azaé Toulouse | C42: Domicile (SAAD / SSIAD / HAD) | D42: SAAD | E42: Azaé (groupe A2micile) | F42: Privé lucratif | G42: 19 rue du Pont Guilhemery | H42: 31000 | I42: Saint-Aubin | J42: 3.5 | K42: 05 61 26 03 46 | L42: https://www.azae.com | M42: à vérifier | N42: — | O42: Aide à domicile / auxiliaire de vie | P42: 2 | Q42: Agence « Toulouse Ouest » à Plaisance-du-Touch (~9 km). | R42: https://www.pagesjaunes.fr/pros/50137970 | S42: À contacter
A43: 42 | B43: Domidom Services Toulouse | C43: Domicile (SAAD / SSIAD / HAD) | D43: SAAD | E43: Domidom | F43: Privé lucratif | G43: 41 rue Bayard | H43: 31000 | I43: Matabiau | J43: 3.5 | K43: à vérifier | L43: https://www.domidom.fr | M43: à vérifier | N43: — | O43: Aide à domicile / auxiliaire de vie | P43: 2 | R43: https://aideadomiciletoulouse.com/liste-des-structures-aide-a-domicile-de-la-region-toulousaine-haute-garonne/ | S43: À contacter
A44: 43 | B44: O2 Toulouse | C44: Domicile (SAAD / SSIAD / HAD) | D44: SAAD | E44: O2 (Oui Care) | F44: Privé lucratif | G44: 40 port Saint-Étienne | H44: 31000 | I44: Saint-Étienne | J44: 3.5 | K44: à vérifier | L44: https://www.o2.fr | M44: à vérifier | N44: — | O44: Aide à domicile / auxiliaire de vie | P44: 2 | Q44: Agence « O2 Toulouse Ouest » à Tournefeuille (93 rue Gaston Doumergue, ~6 km). | R44: https://toulouse-ouest.agence.o2.fr/ | S44: À contacter
A45: 44 | B45: Appel Médical Toulouse (agence Santé) | C45: Intérim / plateforme | D45: Intérim médical | E45: Randstad | F45: Privé lucratif | G45: 9-11 rue Matabiau, Espace Jeanne d'Arc | H45: 31000 | I45: Jeanne d'Arc / Matabiau | J45: 3.5 | K45: 05 34 41 45 15 | L45: https://www.appelmedical.com/agence/1013/ | M45: à vérifier | N45: — | O45: Missions ASH / agent de soins (intérim) | P45: 2 | Q45: Leader national ; missions ASH en EHPAD / clinique / CHU. | R45: https://www.appelmedical.com/agence/1013/ | S45: À contacter
A46: 45 | B46: DomusVi – Résidence Henri IV | C46: EHPAD / résidence | D46: EHPAD (15 places Alzheimer) | E46: DomusVi | F46: Privé lucratif | G46: 1 rue Marie-Louise Dubreil-Jacotin | H46: 31400 | I46: Saint-Agne / Empalot | J46: 4 | K46: 05 61 36 01 01 | L46: https://www.domusvi.com | M46: à vérifier | N46: 88 lits | O46: Agent de soins / ASH (EHPAD) | P46: 2 | R46: https://www.domusvi.com/maisons-de-retraite/haute-garonne-31/residence-henri-iv | S46: À contacter
A47: 46 | B47: EHPAD Sénior Toulouse Tibaous | C47: EHPAD / résidence | D47: EHPAD | E47: SARL Résidence Senior Toulouse Tibaous | F47: Privé lucratif | G47: 1 rue Albert Carovis | H47: 31100 | I47: Tibaous / Saint-Simon | J47: 4 | K47: 05 62 13 41 34 | L47: à vérifier | M47: à vérifier | N47: 80 places | O47: Agent de soins / ASH (EHPAD) | P47: 2 | R47: https://www.pour-les-personnes-agees.gouv.fr/annuaire-ehpad-et-maisons-de-retraite/ehpad/haute-garonne-31/toulouse-31000/ehpad-senior-toulouse-tibaous/310020284 | S47: À contacter
A48: 47 | B48: IUCT-Oncopole – Institut Claudius Regaud | C48: Hôpital | D48: Centre de lutte contre le cancer | E48: Institut Claudius Regaud (Unicancer) | F48: Associatif / ESPIC | G48: 1 avenue Irène Joliot-Curie | H48: 31059 | I48: Oncopole / Langlade | J48: 4.5 | K48: 05 31 15 50 50 | L48: https://recrutement-icr.iuct-oncopole.fr/ | M48: à vérifier | N48: à vérifier | O48: ASH / agent de service | P48: 2 | Q48: Portail RH propre ; offres AS et ASH (CDI/CDD). | R48: https://recrutement-icr.iuct-oncopole.fr/ | S48: À contacter
A49: 48 | B49: Inicea – Clinique Estela | C49: Clinique / SMR | D49: SMR polyvalent et oncologie | E49: Inicea (groupe Clariane) | F49: Privé lucratif | G49: 10 avenue Hubert Curien | H49: 31100 | I49: Oncopole | J49: 4.5 | K49: à vérifier | L49: https://recrutement.inicea.fr | M49: à vérifier | N49: à vérifier | O49: ASH / agent de service | P49: 2 | Q49: Clinique récente ; offres AS en ligne. Inicea propose des parcours VAE à ses salariés. | R49: https://www.inicea.fr/smr/clinique-estela-haute-garonne-31100 | S49: À contacter
A50: 49 | B50: Adhap Services Toulouse | C50: Domicile (SAAD / SSIAD / HAD) | D50: SAAD | E50: Adhap | F50: Privé lucratif | G50: 120 avenue des Minimes | H50: 31200 | I50: Minimes | J50: 4.5 | K50: 05 61 22 40 50 | L50: https://www.adhap.fr | M50: à vérifier | N50: — | O50: Aide à domicile / auxiliaire de vie | P50: 2 | R50: https://www.pour-les-personnes-agees.gouv.fr/annuaire-service-aide-accompagnement-domicile/haute-garonne-31/toulouse-31200/adhap-services/310015649 | S50: À contacter
A51: 50 | B51: ADMR Toulouse (antenne Toulouse Ville) | C51: Domicile (SAAD / SSIAD / HAD) | D51: SAAD | E51: Fédération ADMR Haute-Garonne | F51: Associatif / ESPIC | G51: 142 rue Edmond Rostand | H51: 31200 | I51: Minimes | J51: 4.5 | K51: 05 61 48 11 06 | L51: https://www.fede31.admr.org/toulouse | M51: à vérifier | N51: — | O51: Aide à domicile / auxiliaire de vie | P51: 2 | Q51: Réseau associatif national, recrute sans diplôme. | R51: https://www.fede31.admr.org/toulouse | S51: À contacter
A52: 51 | B52: Résidence Edenis Émeraude | C52: EHPAD / résidence | D52: EHPAD | E52: Edenis (association) | F52: Associatif / ESPIC | G52: 14 rue des Amandiers | H52: 31700 | I52: Blagnac | J52: 5.5 | K52: 05 61 71 44 50 | L52: https://edenis.fr | M52: à vérifier | N52: 90 places | O52: Agent de soins / ASH (EHPAD) | P52: 2 | Q52: Résidence autonomie Émeraude (110 logements) en construction à côté : embauches à venir. | R52: https://www.capgeris.com/ehpad/occitanie/haute-garonne/blagnac/ehpad-residence-emeraude-m17948.htm | S52: À contacter
A53: 52 | B53: Résidence Edenis Les Jardins de Maniban | C53: EHPAD / résidence | D53: EHPAD (13 places Alzheimer) | E53: Edenis (association) | F53: Associatif / ESPIC | G53: 7 chemin des Sœurs | H53: 31700 | I53: Blagnac | J53: 5.5 | K53: 05 82 08 15 23 | L53: https://les-jardins-de-maniban.edenis.fr | M53: à vérifier | N53: 82 lits | O53: Agent de soins / ASH (EHPAD) | P53: 2 | R53: https://les-jardins-de-maniban.edenis.fr/la-residence/ | S53: À contacter
A54: 53 | B54: L'Arche en Pays Toulousain | C54: Handicap (MAS / FAM / IME) | D54: FAM + foyer de vie + foyer d'hébergement | E54: Association L'Arche en Pays Toulousain | F54: Associatif / ESPIC | G54: 2 rue du Docteur Guimbaud | H54: 31700 | I54: Blagnac | J54: 5.5 | K54: 05 62 87 11 20 | L54: à vérifier | M54: contact@archepaystoulousain.org | N54: 38 places (FAM) | O54: Agent de soins / faisant fonction AES | P54: 2 | Q54: Recrute AS / AES ; email direct. | R54: https://www.etablissementsdesante.fr/etablissement/23397-foyer-de-vie-arche-en-pays-toulousain | S54: À contacter
A55: 54 | B55: Inicea – Clinique de Blagnac | C55: Clinique / SMR | D55: SMR gériatrique et neuro-vasculaire | E55: Inicea (groupe Clariane) | F55: Privé lucratif | G55: 11 boulevard Henri Ziegler | H55: 31700 | I55: Blagnac sud | J55: 6 | K55: à vérifier | L55: https://recrutement.inicea.fr | M55: à vérifier | N55: à vérifier | O55: Agent de soins / ASH (EHPAD) | P55: 2 | Q55: Ouverture récente : recrutements en cours probables. | R55: https://www.inicea.fr/actualites/inauguration-nouvelle-clinique-de-blagnac-inicea | S55: À contacter
A56: 55 | B56: Hublo (Pool Hublo) | C56: Intérim / plateforme | D56: Plateforme de remplacements (application) | E56: Hublo | F56: Privé lucratif | G56: 100 % en ligne | H56: — | I56: — | K56: — | L56: https://www.hublo.com/fr/pool-hublo-soignants | M56: à vérifier | N56: — | O56: Missions ASH / agent de soins (intérim) | P56: 2 | Q56: Inscription gratuite ; de nombreux EHPAD et cliniques toulousains y publient leurs remplacements (dont ASH). | R56: https://www.hublo.com/fr/pool-hublo-soignants | S56: À contacter
A57: 56 | B57: HAD Clinique Pasteur | C57: Domicile (SAAD / SSIAD / HAD) | D57: Hospitalisation à domicile | E57: Clinique Pasteur | F57: Privé lucratif | G57: 45 avenue de Lombez | H57: 31300 | I57: Arènes | J57: 1 | K57: 05 62 21 31 31 | L57: https://talents.clinique-pasteur.com | M57: à vérifier | N57: 5 antennes | O57: Aide-soignante (après DEAS) ; ASH en attendant | P57: 3 | Q57: Recrute des AS diplômées : cible après le DEAS. | R57: https://talents.clinique-pasteur.com | S57: À contacter
A58: 57 | B58: Résidence autonomie Tounis (CCAS) | C58: EHPAD / résidence | D58: Résidence autonomie (personnes autonomes) | E58: CCAS de Toulouse | F58: Public | G58: 88 quai de Tounis | H58: 31000 | I58: Carmes / Tounis | J58: 1.5 | K58: 05 61 25 60 08 | L58: https://metropole.toulouse.fr/le-ccas-recrute | M58: recrutement@ccas-toulouse.fr | N58: 28 places | O58: ASH / agent de service | P58: 3 | Q58: Public autonome : peu de soins, plutôt entretien / restauration. | R58: https://www.pour-les-personnes-agees.gouv.fr/annuaire-ehpad-et-maisons-de-retraite/residence-autonomie/haute-garonne-31/toulouse-31000/residence-autonomie-tounis/310786686 | S58: À contacter
A59: 58 | B59: Job-Médical Conseil | C59: Intérim / plateforme | D59: Agence de placement paramédical | E59: Indépendant | F59: Privé lucratif | G59: 31 rue Auguste Guénot | H59: 31100 | I59: Papus / Bagatelle | J59: 2 | K59: 06 61 66 46 57 | L59: à vérifier | M59: à vérifier | N59: — | O59: Missions ASH / agent de soins (intérim) | P59: 3 | Q59: CDD longs en SSIAD (AS diplômées surtout). | R59: https://www.pagesjaunes.fr/pros/51251836 | S59: À contacter
A60: 59 | B60: EHPAD Plénitude Saint-Michel | C60: EHPAD / résidence | D60: EHPAD | E60: à vérifier | F60: Privé lucratif | G60: 28 allées Jules Guesde | H60: 31400 | I60: Saint-Michel | J60: 2.5 | K60: à vérifier | L60: à vérifier | M60: à vérifier | N60: 77 chambres | O60: Agent de soins / ASH (EHPAD) | P60: 3 | Q60: Source indirecte : vérifier l'existence et le gestionnaire avant contact. | R60: https://www.pagesjaunes.fr/annuaire/toulouse-31/maisons-de-retraite-privees-ehpad | S60: À contacter
A61: 60 | B61: ATSAD – Association Toulousaine de Soins à Domicile | C61: Domicile (SAAD / SSIAD / HAD) | D61: SSIAD | E61: ATSAD | F61: Associatif / ESPIC | G61: 18 place Dupuy | H61: 31000 | I61: Centre (rive droite) | J61: 2.8 | K61: 05 61 55 36 17 | L61: https://www.atsad-ssiad.fr | M61: à vérifier | N61: 60 patients | O61: Aide-soignante (après DEAS) ; ASH en attendant | P61: 3 | Q61: Petit SSIAD : cible après le DEAS. | R61: https://www.atsad-ssiad.fr/ | S61: À contacter
A62: 61 | B62: SSIAD Mutualité Française Haute-Garonne | C62: Domicile (SAAD / SSIAD / HAD) | D62: SSIAD | E62: Mutualité Française HG | F62: Associatif / ESPIC | G62: 3 rue du Doyen Lefebvre | H62: 31081 | I62: à vérifier | J62: 3 | K62: à vérifier | L62: à vérifier | M62: à vérifier | N62: à vérifier | O62: Aide-soignante (après DEAS) ; ASH en attendant | P62: 3 | Q62: Coordonnées à vérifier. | R62: https://www.sanitaire-social.com/annuaire-soins-et-aide-a-domicile/services-de-soins-infirmiers-a-domicile-ssiad/liste-toulouse-31000 | S62: À contacter
A63: 62 | B63: UNA Haute-Garonne (fédération) | C63: Domicile (SAAD / SSIAD / HAD) | D63: Tête de réseau d'associations d'aide à domicile | E63: UNA 31 | F63: Associatif / ESPIC | G63: 39 avenue Honoré Serre | H63: 31000 | I63: Compans-Caffarelli | J63: 3 | K63: à vérifier | L63: https://www.una.fr | M63: à vérifier | N63: — | O63: Aide à domicile / auxiliaire de vie | P63: 3 | Q63: Pas un employeur direct : oriente vers ses associations adhérentes. | R63: https://www.pappers.fr/entreprise/una-haute-garonne-499599983 | S63: À contacter
A64: 63 | B64: Institut des Jeunes Aveugles (CESDV-IJA) | C64: Handicap (MAS / FAM / IME) | D64: Institut pour déficients visuels (internat) | E64: Fondation IJA | F64: Associatif / ESPIC | G64: 37 rue Monplaisir | H64: 31400 | I64: Saint-Michel / Busca | J64: 3 | K64: à vérifier | L64: à vérifier | M64: à vérifier | N64: à vérifier | O64: Agent de soins / faisant fonction AES | P64: 3 | Q64: Personnel d'internat ; besoin en AS à vérifier. | R64: https://www.fisaf.asso.fr/adherer-a-la-fisaf/associations-etablissements-services-adherents/item/494-institut-des-jeunes-aveugles-ija-de-toulouse | S64: À contacter
A65: 64 | B65: Résidence autonomie Les Sept Deniers (CCAS) | C65: EHPAD / résidence | D65: Résidence autonomie | E65: CCAS de Toulouse | F65: Public | G65: 4 chemin Garric | H65: 31200 | I65: Sept-Deniers | J65: 3.5 | K65: 05 34 40 00 20 | L65: https://metropole.toulouse.fr/le-ccas-recrute | M65: recrutement@ccas-toulouse.fr | N65: 86 studios | O65: ASH / agent de service | P65: 3 | Q65: Plutôt ASH / auxiliaire de vie. | R65: https://metropole.toulouse.fr/annuaire/residence-autonomie-sept-deniers | S65: À contacter
A66: 65 | B66: IME Enfances Plurielles (ARSEAA) | C66: Handicap (MAS / FAM / IME) | D66: Institut médico-éducatif | E66: ARSEAA | F66: Associatif / ESPIC | G66: 14 rue Paulin Talabot | H66: 31100 | I66: Basso Cambo / Saint-Simon | J66: 4.5 | K66: 05 61 43 06 04 | L66: https://www.arseaa.org/pole-enfances-plurielles | M66: à vérifier | N66: à vérifier | O66: Agent de soins / faisant fonction AES | P66: 3 | Q66: Siège ARSEAA : 7 chemin de Colasson, 31081 Toulouse. | R66: https://www.arseaa.org/pole-enfances-plurielles | S66: À contacter
...

Sheet Tableau de bord
B1: Tableau de bord de la prospection
B2: Se met à jour automatiquement à partir de l'onglet Prospection (colonnes S, P, C, X).
B4: Indicateurs clés | C4: Valeur | F4: Par catégorie | G4: Nombre
B5: Structures recensées | C5: =COUNTA(Prospection!$B$2:$B$300) -> 73 | F5: Hôpital | G5: =COUNTIF(Prospection!$C$2:$C$300,F5) -> 10
B6: Structures en priorité 1 | C6: =COUNTIF(Prospection!$P$2:$P$300,1) -> 18 | F6: Clinique / SMR | G6: =COUNTIF(Prospection!$C$2:$C$300,F6) -> 9
B7: Structures déjà contactées (statut différent de « À contacter ») | C7: =COUNTIFS(Prospection!$B$2:$B$300,"<>",Prospection!$S$2:$S$300,"<>À contacter") -> 0 | F7: EHPAD / résidence | G7: =COUNTIF(Prospection!$C$2:$C$300,F7) -> 23
B8: Taux de couverture | C8: =IF(C5=0,0,C7/C5) -> 0 | F8: Domicile (SAAD / SSIAD / HAD) | G8: =COUNTIF(Prospection!$C$2:$C$300,F8) -> 18
B9: Relances en retard (date dépassée, dossier encore ouvert) | C9: =COUNTIFS(Prospection!$X$2:$X$300,"<"&TODAY(),Prospection!$S$2:$S$300,"<>Clos",Prospection!$S$2:$S$300,"<>Embauche / positif",Prospection!$S$2:$S$300,"<>Réponse négative") -> 0 | F9: Handicap (MAS / FAM / IME) | G9: =COUNTIF(Prospection!$C$2:$C$300,F9) -> 5
B10: Relances prévues dans les 7 prochains jours | C10: =COUNTIFS(Prospection!$X$2:$X$300,">="&TODAY(),Prospection!$X$2:$X$300,"<="&TODAY()+7) -> 0 | F10: Intérim / plateforme | G10: =COUNTIF(Prospection!$C$2:$C$300,F10) -> 8
B11: Entretiens obtenus | C11: =COUNTIF(Prospection!$S$2:$S$300,"Entretien") -> 0 | F11: Total | G11: =SUM(G5:G10) -> 73
B12: Réponses positives / embauche | C12: =COUNTIF(Prospection!$S$2:$S$300,"Embauche / positif") -> 0
B14: Par statut de suivi | C14: Nombre | D14: Part | F14: Par priorité | G14: Nombre
B15: À contacter | C15: =COUNTIF(Prospection!$S$2:$S$300,B15) -> 73 | D15: =IF($C$5=0,0,C15/$C$5) -> 1 | F15: Priorité 1 | G15: =COUNTIF(Prospection!$P$2:$P$300,1) -> 18
B16: Contacté – en attente | C16: =COUNTIF(Prospection!$S$2:$S$300,B16) -> 0 | D16: =IF($C$5=0,0,C16/$C$5) -> 0 | F16: Priorité 2 | G16: =COUNTIF(Prospection!$P$2:$P$300,2) -> 37
B17: Relance à faire | C17: =COUNTIF(Prospection!$S$2:$S$300,B17) -> 0 | D17: =IF($C$5=0,0,C17/$C$5) -> 0 | F17: Priorité 3 | G17: =COUNTIF(Prospection!$P$2:$P$300,3) -> 18
B18: Entretien | C18: =COUNTIF(Prospection!$S$2:$S$300,B18) -> 0 | D18: =IF($C$5=0,0,C18/$C$5) -> 0
B19: Embauche / positif | C19: =COUNTIF(Prospection!$S$2:$S$300,B19) -> 0 | D19: =IF($C$5=0,0,C19/$C$5) -> 0 | F19: Par poste à viser | G19: Nombre
B20: Réponse négative | C20: =COUNTIF(Prospection!$S$2:$S$300,B20) -> 0 | D20: =IF($C$5=0,0,C20/$C$5) -> 0 | F20: Agent de soins / ASH (EHPAD) | G20: =COUNTIF(Prospection!$O$2:$O$300,F20) -> 23
B21: Clos | C21: =COUNTIF(Prospection!$S$2:$S$300,B21) -> 0 | D21: =IF($C$5=0,0,C21/$C$5) -> 0 | F21: ASH / agent de service | G21: =COUNTIF(Prospection!$O$2:$O$300,F21) -> 19
B22: Total | C22: =SUM(C15:C21) -> 73 | D22: =SUM(D15:D21) -> 1 | F22: Aide à domicile / auxiliaire de vie | G22: =COUNTIF(Prospection!$O$2:$O$300,F22) -> 13
F23: Agent de soins / faisant fonction AES | G23: =COUNTIF(Prospection!$O$2:$O$300,F23) -> 5
F24: Missions ASH / agent de soins (intérim) | G24: =COUNTIF(Prospection!$O$2:$O$300,F24) -> 8
F25: Aide-soignante (après DEAS) ; ASH en attendant | G25: =COUNTIF(Prospection!$O$2:$O$300,F25) -> 5
F27: Date du jour (référence des relances) | G27: =TODAY() -> 46295

Sheet Parcours administratif
A1: Étape | B1: Thème | C1: Ce qu'il faut savoir | D1: Action concrète | E1: Organisme / où | F1: Pièces | G1: Délai / coût | H1: Source | I1: Fait ? (Oui / En cours / Non) | J1: Notes / dates
A2: 1 | B2: Diplôme camerounais | C2: Aucune équivalence ni reconnaissance n'existe en France pour un diplôme d'aide-soignant obtenu hors UE/EEE/Suisse (Croix-Rouge Cameroun inclus). La DREETS ne peut rien délivrer. Le titre d'aide-soignant ne peut pas être utilisé sans le DEAS français (usurpation de titre, art. L4394-1 CSP). | D2: Ne pas viser un poste intitulé « aide-soignante » tant que le DEAS n'est pas obtenu. Viser ASH / agent de soins / aide à domicile, et lancer en parallèle la VAE ou l'IFAS. | E2: DREETS Occitanie (confirme l'absence de procédure) : dreets-oc.diplomes-paramedicaux@dreets.gouv.fr – 09 88 88 80 83 | F2: Copie de l'attestation de réussite (suffit pour toutes les démarches ci-dessous, l'original n'est jamais exigé). | G2: — | H2: https://bourgogne-franche-comte.dreets.gouv.fr/Dispositif-de-reconnaissance-des-diplomes-paramedicaux | I2: Non
A3: 2 | B3: Attestation de réussite vs original | C3: Au Cameroun le diplôme MINSANTE n'est pas réédité en cas de perte, mais une attestation de réussite a la même valeur juridique. Depuis 2019-2020 les diplômes sont authentifiables par QR code sur scolarite.minsante.cm. Documents en français : aucune traduction assermentée nécessaire. | D3: Créer/consulter l'espace personnel sur scolarite.minsante.cm pour télécharger le PDF authentifiable ; sinon demander une copie certifiée à l'école Croix-Rouge ou à la Délégation régionale de la Santé publique (procuration à un proche au Cameroun). | E3: MINSANTE Cameroun – https://scolarite.minsante.cm (vérification : /diplome/verify) ; Consulat du Cameroun à Paris, 73 rue d'Auteuil 75016 (légalisation seulement, pas de duplicata). | F3: Pièce d'identité, attestation actuelle, relevés de notes. | G3: Variable (Cameroun) ; légalisation consulat 15 €/document (non exigée pour IFAS/VAE/AT). | H3: https://echosante.info/authentification-des-diplomes-le-minsante-opte-pour-un-code-barre/ | I3: Non
A4: 3 | B4: ENIC-NARIC (optionnel) | C4: Attestation de comparabilité : avis qui situe le diplôme dans le système français. Ce n'est ni une équivalence ni un droit d'exercer. ENIC-NARIC accepte « le diplôme ou, à défaut, l'attestation de réussite ». Plusieurs guides indiquent qu'il ne délivre pas d'attestation pour les professions paramédicales réglementées : demande possiblement refusée. | D4: Utilité faible pour ce projet. À faire seulement si un employeur ou un accompagnateur VAE le demande. | E4: France Éducation international – ENIC-NARIC (en ligne) | F4: Pièce d'identité, diplôme ou attestation de réussite, relevés de notes / durée des études. | G4: 120 € (gratuit réfugiés/demandeurs d'asile) ; ~4 mois (jusqu'à 6). | H4: https://www.service-public.gouv.fr/particuliers/vosdroits/R38515 | I4: Non
A5: 4 | B5: Postes accessibles sans DEAS | C5: ASH / ASHQ : aucun diplôme exigé (hygiène des locaux, hôtellerie, aide aux repas, pas d'actes de soins). Après la formation de 70 h « participation aux soins d'hygiène, de confort et de bien-être », l'ASH peut participer à ces soins sous responsabilité d'un cadre. Aide à domicile degré 1 (CCN BAD) : sans diplôme. Ces emplois construisent l'expérience française pour la VAE et ouvrent la voie IFAS « article 11 ». | D5: Cibler dans le fichier Prospection : ASH (hôpitaux, cliniques, EHPAD), agent de soins / agent hôtelier (EHPAD), aide à domicile / auxiliaire de vie (SAAD, SSIAD). Demander la formation 70 h dès l'embauche. | E5: Formation 70 h à Toulouse : GRETA Toulouse-Pyrénées (Lycée Hélène Boucher) ; Croix-Rouge Compétence Occitanie 05 61 31 56 70. | F5: CV mettant en avant l'expérience camerounaise (soins d'hygiène et de confort), attestation de réussite en pièce jointe. | G5: Formation 70 h : souvent financée par l'employeur (OPCO / ANFH). | H5: https://www.croix-rouge.fr/formation-professionnelle/agent-des-services-hospitaliers-ash-renfort-aux-aides-soignants | I5: Non
A6: 5 | B6: Autorisation de travail (AT) | C6: Déposée uniquement par l'EMPLOYEUR, en ligne sur l'ANEF. La DREETS n'instruit plus : ce sont les plateformes interrégionales de main-d'œuvre étrangère (préfectures). Critères (R5221-20 C. trav.) : métier en tension OU offre publiée 3 semaines à France Travail ; salaire ≥ SMIC/minimum conventionnel ; employeur à jour URSSAF ; adéquation qualification/emploi. Silence de 2 mois = rejet implicite. | D6: Rassurer l'employeur : procédure en ligne, gratuite, sans publication d'offre si le métier est en tension (voir étape 6). Lui fournir la liste des pièces prête à l'emploi (voir onglet Modèles). | E6: ANEF : https://administration-etrangers-en-france.interieur.gouv.fr – assistance DGEF 0 806 001 620 (gratuit). | F6: Formulaire ANEF, Kbis/SIRET, contrat ou promesse d'embauche, pièce d'identité + titre/récépissé de la salariée, CV + copies diplômes (France et étranger) + attestations d'activité, attestation de vigilance URSSAF < 6 mois (arrêté du 3 janvier 2025). | G6: Gratuit ; réponse sous 2 mois maximum. | H6: https://www.service-public.gouv.fr/particuliers/vosdroits/F2728 | I6: Non
A7: 6 | B7: Métiers en tension – Occitanie | C7: Arrêté du 21 mai 2025 (toujours en vigueur au 30/09/2026). En Occitanie figurent : V0Z60 Aides-soignants, T2A60 Aides à domicile et aides ménagères, T4Z60 Agents d'entretien de locaux (FAP la plus proche d'un poste ASH). Conséquence : pas d'opposabilité de la situation de l'emploi → l'employeur n'a pas à publier l'offre 3 semaines. | D7: Sur la promesse d'embauche, faire libeller le poste avec un intitulé qui correspond à une FAP en tension (aide à domicile, agent d'entretien / ASH) et le rappeler dans le dossier ANEF. Faire confirmer la FAP par la plateforme si doute. | E7: Texte : https://www.legifrance.gouv.fr/jorf/id/JORFTEXT000051643488 | F7: — | G7: — | H7: https://www.entreprises-occitanie.com/actualites/occitanie-35-metiers-en-tension-dans-la-nouvelle-liste-nationale | I7: Non
A8: 7 | B8: Titres de séjour dispensant d'AT | C8: Dispensent d'AT (R5221-2) : carte de résident, carte « vie privée et familiale », réfugié/protection subsidiaire, « talent », récépissé/APS portant la mention « autorise son titulaire à travailler ». Étudiant : 964 h/an sans AT (au-delà, AT). Récépissé de renouvellement : autorise à travailler si le titre précédent le permettait. Demandeur d'asile : AT possible si l'OFPRA n'a pas statué après 6 mois. | D8: Vérifier la mention exacte du titre / récépissé actuel : si elle autorise à travailler, l'employeur n'a AUCUNE démarche ANEF à faire (argument décisif à mettre en avant dans la candidature). | E8: Préfecture de la Haute-Garonne – Direction des migrations et de l'intégration : 1 place Saint-Étienne, 31038 Toulouse – 05 34 45 34 45 – pref-sejour@haute-garonne.gouv.fr | F8: Titre de séjour ou récépissé en cours de validité. | G8: — | H8: https://code.travail.gouv.fr/code-du-travail/r5221-2 | I8: Non
A9: 8 | B9: Si sans titre : AES « métiers en tension » | C9: Art. L435-4 CESEDA (loi du 26 janvier 2024) : carte « salarié » ou « travailleur temporaire » d'1 an valant AT, délivrée sans accord de l'employeur, si : ≥ 3 ans de résidence habituelle en France, ≥ 12 mois d'activité salariée sur les 24 derniers mois dans un métier en tension, emploi actuel en tension. DISPOSITIF EXPÉRIMENTAL JUSQU'AU 31/12/2026, aucune prorogation connue. | D9: Si elle remplit les conditions : déposer la pré-demande Haute-Garonne AVANT fin 2026, avec l'aide de La Cimade ou du CIDFF. Sinon : voie AES « salarié » de droit commun (circulaire Valls) à étudier avec un juriste. | E9: Pré-demande : https://demarche.numerique.gouv.fr/commencer/metiers-en-tension-haute-garonne – Préfecture, service AES, 1 rue Sainte-Anne, 31000 Toulouse | F9: Preuves de résidence (3 ans), bulletins de paie / attestations (12 mois sur 24), contrat actuel, contrat d'engagement républicain. | G9: Timbre fiscal à la délivrance ; délais préfectoraux longs → anticiper. | H9: https://www.service-public.gouv.fr/particuliers/vosdroits/F16053 | I9: Non
A10: 9 | B10: VAE du DEAS | C10: Plus de durée minimale légale d'expérience depuis le décret du 27/12/2023, mais le repère pratique d'1 an / 1 607 h reste utilisé. L'expérience acquise au Cameroun est recevable sur justificatifs (attestations d'employeur, contrats). Dossier sur France VAE avec un Architecte Accompagnateur de Parcours, puis dossier de validation et jury (oral 30-45 min). AFGSU 2 exigée au jury. Le DEAS est enregistré RNCP 40692 (2025-2029). | D10: Ouvrir un compte sur vae.gouv.fr, choisir « Diplôme d'État d'aide-soignant », se faire rappeler par un accompagnateur en Occitanie. Rassembler dès maintenant les attestations d'employeurs camerounais (dates, fonctions, activités réalisées). | E10: France VAE : https://vae.gouv.fr/certifications/91d7991a-eb28-43ca-a07d-0a4d9c142565/ – Résultats jurys : DREETS Occitanie | F10: Attestations d'expérience détaillées, contrats, bulletins ; attestation de réussite ; pièce d'identité. | G10: Recevabilité notifiée sous 2 mois ; parcours 6 à 12 mois. Financement : CPF (reste à charge ~103 €), France Travail (demandeurs d'emploi), Transitions Pro (2 000 €, salariés privé, décret du 27/07/2026). | H10: https://vae.gouv.fr | I10: Non
A11: 10 | B11: Formation DEAS en IFAS | C11: Sélection sur dossier + entretien, sans condition de diplôme ; titre de séjour valide exigé à l'entrée. Le diplôme camerounais n'ouvre aucune dispense (cursus complet 1 540 h, ~11 mois). Voie « article 11 » : les ASH avec 1 an d'ancienneté (ou 6 mois + formation 70 h) sont admis SANS sélection, ≥ 20 % des places réservées. | D11: Stratégie : travailler comme ASH 6 mois + formation 70 h → entrée directe en IFAS. S'inscrire à France Travail AVANT l'entrée pour la gratuité Région Occitanie. Voir onglet « IFAS & formations » pour les dates. | E11: Région Occitanie – formations sanitaires et sociales : https://www.laregion.fr/formations-sanitaires-sociales ; bourses : https://www.laregion.fr/bourses-etudes-sanitaires-sociales | F11: Dossier IFAS (CV, lettre, attestation de réussite, attestations d'expérience, titre de séjour). | G11: Gratuit si demandeuse d'emploi inscrite à France Travail (sinon ~8 470 €/an à la Croix-Rouge). | H11: https://www.anfh.fr/actualites/deas-et-deap-nouvelles-modifications-des-conditions-d-acces-aux-formations | I11: Non

Sheet IFAS & formations
A1: Établissement | B1: Statut | C1: Adresse | D1: Téléphone | E1: Email | F1: Site | G1: Sélection 2026 | H1: Rentrée | I1: Remarque | J1: Dossier déposé ? / notes
A2: IFAS PREFMS – CHU de Toulouse | B2: Public (150 places) | C2: 74 voie du TOEC, TSA 40031, 31059 Toulouse Cedex 9 (site Purpan, ~3 km des Arènes) | D2: 05 61 32 40 60 / 05 61 77 22 33 | E2: ifas.sec@chu-toulouse.fr ; ifas.selection@chu-toulouse.fr | F2: https://ecoles-instituts.chu-toulouse.fr/concours-et-selections/ifas/ | G2: Inscriptions 2 mars → 10 juin 2026 ; oraux 8-22 juin 2026 (session 2027 : à vérifier) | H2: 24 août 2026 (rentrée janvier 2027 : à vérifier) | I2: Le plus proche des Arènes. Voie « article 11 » pour les ASH du CHU.
A3: Croix-Rouge Compétence Occitanie – IFAS Toulouse | B3: Associatif | C3: 71 chemin des Capelles, 31300 Toulouse (Purpan / Casselardit, ~2,5 km) | D3: 05 61 31 56 12 / 05 61 31 56 69 | E3: ifas.toulouse@croix-rouge.fr | F3: https://www.croix-rouge.fr/formation-professionnelle/aide-soignant-toulouse | G3: Session 2 : 1er avril → 10 octobre 2026, résultats 13 novembre 2026 | H3: 5 janvier 2027 | I3: ENCORE OUVERT au 30/09/2026. Même réseau que son école au Cameroun : à valoriser à l'entretien. Aussi formation 70 h ASH (05 61 31 56 70).
A4: IFRASS – Pôle Santé | B4: Associatif | C4: 2 bis rue Émile Pelletier, BP 44777, 31047 Toulouse Cedex 1 (Rangueil) | D4: 05 34 63 89 02 | E4: secretariat-AS@ifrass.fr | F4: https://www.ifrass.fr/pole-sante/diplome-detat-daide-soignant-e/ | G4: Dossier + entretien ; dates 2026-2027 à vérifier | H4: à vérifier | I4: Règlement d'admission exige un titre de séjour valide à l'entrée.
A5: IFAS Lycée Hélène Boucher – GRETA Toulouse-Pyrénées | B5: Public (Éducation nationale) | C5: 1 rue Lucien Lafforgue, 31000 Toulouse | D5: 05 34 45 24 09 | E5: ifas.ifap.heleneboucher@gmail.com | F5: à vérifier | G5: 2025 : 24 mars → 10 juin ; 2026-2027 à vérifier | H5: septembre | I5: Le GRETA propose aussi la formation 70 h ASH.
A6: IFAS AEHP / FHP Occitanie Formation | B6: Privé (hospitalisation privée) | C6: Boulevard de Ratalens, 31240 Saint-Jean (~12 km) | D6: 04 67 13 89 41 | E6: aehp_31@fhpoccitanieformation.fr | F6: à vérifier | G6: 7 avril → 30 juin 2026 | H6: 31 août 2026 | I6: Lié aux cliniques privées (Pasteur, Médipôle…) : débouchés directs.
A8: À savoir
A9: • Repères : sélection sur dossier + entretien (pas d'écrit), aucune condition de diplôme, titre de séjour valide exigé à l'entrée. Cursus complet ~11 mois (1 540 h), le diplôme camerounais n'ouvre aucune dispense.
A10: • Voie « article 11 » (arrêté du 7 avril 2020 modifié) : les ASH avec 1 an d'ancienneté, ou 6 mois + formation 70 h, entrent SANS sélection ; au moins 20 % des places leur sont réservées.
A11: • Gratuité : la Région Occitanie prend en charge les frais pédagogiques des demandeurs d'emploi inscrits à France Travail avant l'entrée en formation ; bourses possibles (https://www.laregion.fr/bourses-etudes-sanitaires-sociales).
A12: • Formation 70 h ASH « participation aux soins d'hygiène, de confort et de bien-être » : GRETA Toulouse-Pyrénées (Lycée Hélène Boucher) et Croix-Rouge Compétence Occitanie (05 61 31 56 70) ; souvent financée par l'employeur.
A13: • VAE du DEAS : https://vae.gouv.fr (choisir « Diplôme d'État d'aide-soignant ») ; parcours 6 à 12 mois ; CPF, France Travail ou Transitions Pro.

Sheet Contacts utiles
A1: Organisme | B1: Rôle pour elle | C1: Adresse | D1: Téléphone | E1: Email / site | F1: Remarque | G1: Contacté ? / notes
A2: DREETS Occitanie | B2: Confirme l'absence d'équivalence ; jurys VAE DEAS ; renseignements | C2: 1 place Émile Blouin, CS 90007, 31952 Toulouse Cedex 9 | D2: 09 88 88 80 80 (standard) ; 09 88 88 80 83 (diplômes paramédicaux) | E2: dreets-oc.diplomes-paramedicaux@dreets.gouv.fr – https://occitanie.dreets.gouv.fr/paramedical | F2: Ne traite PLUS les autorisations de travail (→ ANEF).
A3: ANEF – autorisations de travail (employeur) | B3: Dépôt de la demande d'AT par l'employeur | C3: En ligne | D3: 0 806 001 620 (assistance DGEF, gratuit) | E3: https://administration-etrangers-en-france.interieur.gouv.fr | F3: Réponse sous 2 mois ; silence = rejet implicite.
A4: Préfecture de la Haute-Garonne – Direction des migrations et de l'intégration | B4: Titre de séjour, récépissé, admission exceptionnelle au séjour | C4: 1 place Saint-Étienne, 31038 Toulouse Cedex 9 ; service AES : 1 rue Sainte-Anne, 31000 | D4: 05 34 45 34 45 | E4: pref-sejour@haute-garonne.gouv.fr – https://www.haute-garonne.gouv.fr/Demarches-administratives/Immigration-et-integration | F4: Point d'accueil numérique sur rendez-vous. Pré-demande AES métiers en tension : https://demarche.numerique.gouv.fr/commencer/metiers-en-tension-haute-garonne
A5: France Travail – agence Toulouse Arènes | B5: Inscription (indispensable pour la gratuité IFAS), offres ASH / aide à domicile, financement VAE | C5: 36 boulevard Gabriel Koenigs, 31300 Toulouse (Saint-Cyprien) | D5: 39 49 | E5: https://prendresoin.francetravail.fr | F5: Agence de secteur pour les Arènes. Autres : Bellefontaine (63 allée de Bellefontaine, 31100), Saint-Simon (280 route de Saint-Simon, 31100).
A6: Nova Emploi (ex Toulouse Métropole Emploi) | B6: Accompagnement emploi, ateliers, mise en relation employeurs | C6: 32 rue de la Caravelle, 31500 Toulouse | D6: 05 31 47 17 33 / 06 18 86 55 59 | E6: https://nova-emploi.fr | F6: Renommé en 2025.
A7: La Cimade Toulouse | B7: Aide juridique séjour / AES / autorisation de travail | C7: 16 rue de Tivoli, 31000 Toulouse | D7: 05 61 41 13 20 | E7: toulouse@lacimade.org – https://www.lacimade.org/regions/sud-ouest/ | F7: Permanence téléphonique lundi et jeudi dès 14 h ; accueil sur RDV.
A8: CIDFF Haute-Garonne | B8: Accompagnement juridique et emploi des femmes | C8: 95 Grande rue Saint-Michel, 31400 Toulouse | D8: 05 34 31 23 31 | E8: cidff31@cidff31.fr – https://hautegaronne.cidff.info/ | F8: Lun-ven 9h-12h / 13h30-17h.
A9: Forum réfugiés Toulouse | B9: Accompagnement des demandeurs d'asile / réfugiés | C9: 393 route de Saint-Simon, 31100 Toulouse | D9: 05 32 78 01 60 | E9: https://www.forumrefugies.org | F9: Si elle relève de l'asile.
A10: La Case de Santé – pôle Santé-Droits | B10: Accès aux droits, santé | C10: 17 place Arnaud-Bernard, 31000 Toulouse | D10: 05 61 23 62 35 | E10: à vérifier | F10: —
A11: France VAE | B11: Dossier VAE DEAS, mise en relation avec un accompagnateur | C11: En ligne | D11: — | E11: https://vae.gouv.fr | F11: Choisir la certification « Diplôme d'État d'aide-soignant ».
A12: Région Occitanie – formations sanitaires et sociales | B12: Gratuité de la formation IFAS pour demandeurs d'emploi, bourses | C12: En ligne | D12: — | E12: https://www.laregion.fr/formations-sanitaires-sociales – https://www.meformerenregion.fr/dispositifs/sanitaire-et-social | F12: Être inscrite à France Travail AVANT l'entrée en formation.
A13: ENIC-NARIC France (France Éducation international) | B13: Attestation de comparabilité (optionnelle) | C13: En ligne | D13: — | E13: https://www.service-public.gouv.fr/particuliers/vosdroits/R38515 | F13: 120 € ; ~4 mois ; peut refuser les professions paramédicales réglementées.
... A15: MINSANTE Cameroun – scolarité | B15: Téléchargement / authentification du diplôme (QR code) | C15: En ligne | D15: — | E15: https://scolarite.minsante.cm (vérification : https://scolarite.minsante.cm/diplome/verify) | F15: Alternative à l'original : attestation de réussite de même valeur.

Sheet Modèles
B1: Modèles de candidature et argumentaires (à adapter : remplacer les crochets [ ])
B2: Conseil : joindre systématiquement un CV d'une page, la copie de l'attestation de réussite et, si possible, une attestation d'employeur du Cameroun. Ne jamais écrire « aide-soignante » comme poste recherché tant que le DEAS n'est pas obtenu ; écrire « agent de soins », « ASH » ou « auxiliaire de vie », et mentionner la formation d'aide-soignante comme atout.
B4: MODÈLE 1 – Email de candidature spontanée : agent de soins / ASH en EHPAD, clinique ou hôpital
B5: Objet : Candidature spontanée – agent de soins / ASH – disponible immédiatement Madame, Monsieur, Formée au métier d'aide-soignante au Cameroun (école de la Croix-Rouge, diplôme obtenu en [année]) et forte de [X] années d'expérience en [service : gériatrie, médecine, chirurgie…], je souhaite rejoindre votre équipe comme agent de soins ou agent de service hospitalier, en attendant d'obtenir le diplôme d'État français d'aide-soignant par la VAE que j'engage cette année. Au quotidien, j'ai assuré les soins d'hygiène et de confort, l'aide aux repas et à la mobilisation, la surveillance de l'état des résidents et la transmission des observations à l'équipe infirmière. Je connais les règles d'hygiène et l'organisation d'un service, et j'aime le travail en équipe auprès des personnes âgées. J'habite le quartier des Arènes, à [X] minutes de votre établissement, et je suis disponible en jour comme en nuit, week-ends compris. Concernant l'autorisation de travail : [Option A : mon titre de séjour m'autorise à travailler, aucune démarche n'est nécessaire de votre part.] [Option B : les postes d'aide à domicile, d'agent d'entretien / ASH et d'aide-soignant figurent sur la liste des métiers en tension en Occitanie (arrêté du 21 mai 2025). La demande se fait en ligne sur le portail ANEF, sans publication préalable de l'offre ; je vous transmets un dossier complet avec toutes les pièces pour vous faciliter la démarche.] Je serais heureuse de vous rencontrer et de vous présenter mes attestations. Je vous remercie de l'attention portée à ma candidature. [Prénom NOM] – [téléphone] – [email] Pièces jointes : CV, attestation de réussite (Croix-Rouge Cameroun), attestation(s) d'employeur.
B7: MODÈLE 2 – Email de candidature : aide à domicile / auxiliaire de vie (SAAD, SSIAD, mandataire)
B8: Objet : Candidature – auxiliaire de vie / aide à domicile – secteur Toulouse ouest Madame, Monsieur, Formée aide-soignante au Cameroun et expérimentée dans l'accompagnement des personnes âgées et dépendantes ([X] années), je recherche un poste d'auxiliaire de vie ou d'aide à domicile sur le secteur des Arènes, Saint-Cyprien, Purpan, Lardenne et Saint-Simon. Je maîtrise l'aide à la toilette, à l'habillage, aux transferts et aux repas, l'entretien du cadre de vie et l'accompagnement dans les gestes quotidiens, dans le respect de la personne et de son rythme. Je suis ponctuelle, discrète et à l'aise avec les familles. Disponible [temps plein / temps partiel], [en semaine et week-end], je me déplace [en transports en commun / en voiture]. Le métier d'aide à domicile est inscrit sur la liste des métiers en tension pour l'Occitanie : la demande d'autorisation de travail, si elle est nécessaire, se fait en ligne sur le portail ANEF sans publication préalable de l'offre, et je vous fournis un dossier complet. Je reste à votre disposition pour un entretien. [Prénom NOM] – [téléphone] – [email]
B10: MODÈLE 3 – Script téléphonique (30 secondes) pour un premier appel à un EHPAD ou une clinique
B11: « Bonjour, [Prénom NOM]. Je vous appelle pour une candidature d'agent de soins. J'ai été formée aide-soignante au Cameroun et j'ai [X] ans d'expérience en soins d'hygiène et de confort auprès des personnes âgées. J'habite aux Arènes, je suis disponible tout de suite, de jour comme de nuit. Pourriez-vous me dire qui s'occupe des recrutements et si je peux lui envoyer mon CV, ou passer le déposer ? » Si l'interlocuteur demande le diplôme : « Mon diplôme camerounais n'est pas reconnu en France, c'est pourquoi je postule comme agent de soins / ASH et je prépare le DEAS par la VAE. Mon expérience des gestes de soins est un vrai plus pour l'équipe. » Si l'interlocuteur évoque l'autorisation de travail : « C'est une démarche en ligne, gratuite, que fait l'employeur sur le portail ANEF ; le métier est en tension en Occitanie donc pas besoin de publier l'offre. Je peux vous envoyer la liste des pièces et un mode d'emploi en une page. » Toujours terminer par : nom de l'interlocuteur, adresse email de dépôt, date de rappel. Reporter dans l'onglet Prospection (colonnes S à Y).
B13: MODÈLE 4 – Note d'une page pour l'employeur : « Recruter une salariée étrangère : l'autorisation de travail en pratique »
B14: 1. Qui fait la demande ? L'employeur, en ligne, sur le portail ANEF : https://administration-etrangers-en-france.interieur.gouv.fr (rubrique « Demande d'autorisation de travail »). Gratuit. Assistance : 0 806 001 620. 2. Faut-il publier l'offre 3 semaines à France Travail ? NON pour les emplois d'aide à domicile, d'agent d'entretien de locaux (poste ASH) et d'aide-soignant en Occitanie, qui figurent sur la liste des métiers en tension (arrêté du 21 mai 2025, tableau Occitanie). La « situation de l'emploi » n'est pas opposable. 3. Quelles conditions ? Salaire au moins égal au SMIC ou au minimum de la convention collective ; employeur à jour de ses cotisations (attestation de vigilance URSSAF de moins de 6 mois) ; adéquation entre le poste et le profil (CV, expérience). 4. Quelles pièces ? Formulaire en ligne ; extrait Kbis / SIRET ; contrat de travail ou promesse d'embauche signée (intitulé du poste, durée, salaire) ; attestation de vigilance URSSAF ; copie du passeport et du titre ou récépissé de séjour de la salariée ; CV, copies des diplômes et attestations d'expérience (fournis par la salariée). 5. Quel délai ? Instruction par la plateforme de main-d'œuvre étrangère de la préfecture ; réponse sous 2 mois maximum. La salariée peut commencer dès réception de l'autorisation (ou immédiatement si son titre de séjour l'autorise déjà à travailler). 6. Et si le titre de séjour de la salariée l'autorise déjà à travailler (carte « vie privée et familiale », récépissé portant la mention « autorise son titulaire à travailler », carte de résident) ? Aucune démarche : embauche comme pour toute salariée (DPAE, vérification du titre auprès de la préfecture sous 2 jours ouvrables avant l'embauche, art. R5221-41 code du travail). Sources : service-public.gouv.fr/particuliers/vosdroits/F2728 ; legifrance.gouv.fr/jorf/id/JORFTEXT000051643488 (métiers en tension) ; code du travail art. R5221-20 et R5221-2.
B16: MODÈLE 5 – Réponses aux objections
B17: « Vous n'avez pas le DEAS. » → « C'est exact, et c'est pourquoi je postule comme agent de soins / ASH, pas comme aide-soignante. Ma formation et mon expérience des gestes de soins me permettent d'être opérationnelle vite, et je prépare le DEAS par la VAE. Après 6 mois chez vous et la formation de 70 heures, je peux aussi entrer directement en IFAS. » « L'autorisation de travail, c'est trop compliqué. » → « C'est une démarche en ligne d'une trentaine de minutes, gratuite, sans publication d'offre puisque le métier est en tension en Occitanie. Je vous apporte le dossier complet et la notice d'une page. Beaucoup d'EHPAD du secteur le font régulièrement. » « Vous n'avez qu'une attestation, pas le diplôme. » → « Au Cameroun, le ministère de la Santé ne réédite pas les diplômes : l'attestation de réussite a la même valeur, et le diplôme est authentifiable en ligne par QR code sur le site du ministère (scolarite.minsante.cm). De toute façon, pour un poste d'agent de soins, aucun diplôme n'est exigé : ce sont mes attestations d'expérience qui comptent. » « Nous ne prenons que des intérimaires. » → « Je peux m'inscrire chez [Adecco Medical / Appel Médical / Domino Care] et via Hublo pour effectuer des missions chez vous ; cela vous permet de me voir travailler avant un CDD. » « Repassez quand vous aurez le diplôme. » → « Puis-je laisser mon CV pour les remplacements d'agent de soins, les week-ends et les congés d'été ? Et puis-je vous rappeler dans un mois ? » (noter la date de relance).
... B20: À préparer une fois, en PDF, dans un dossier nommé « Candidature – [NOM] » : ☐ CV d'une page (titre : « Agent de soins / auxiliaire de vie – formée aide-soignante, [X] ans d'expérience »), avec la mention « VAE DEAS en cours » dès l'inscription sur vae.gouv.fr. ☐ Lettre de motivation (Modèle 1 ou 2), personnalisée : nom de la structure, distance, disponibilité. ☐ Copie de l'attestation de réussite (Croix-Rouge Cameroun) + relevé de notes si disponible ; PDF authentifiable téléchargé sur scolarite.minsante.cm si possible. ☐ Attestations d'employeurs du Cameroun (dates, service, tâches réalisées) : indispensables aussi pour la VAE. ☐ Copie du passeport et du titre de séjour / récépissé (vérifier la mention relative au travail). ☐ Attestation d'inscription à France Travail (pour la gratuité IFAS et le financement VAE). ☐ Note d'une page pour l'employeur (Modèle 4) : à joindre uniquement si une autorisation de travail est nécessaire. ☐ Attestation de formation AFGSU si déjà suivie (sinon, la prévoir avant le jury VAE). ☐ Justificatif de domicile (utile pour la préfecture et les employeurs). ☐ Pour l'admission exceptionnelle au séjour « métiers en tension », si concernée : preuves de 3 ans de résidence, bulletins de paie ou attestations couvrant 12 mois sur les 24 derniers, à déposer avant le 31/12/2026.
